Workbook

Sheet 一览表
A1: 报表数据截止时间 | B1: 46104
A2: 序号 | B2: 趋势预警 | C2: 本月交易预警 | D2: 流失情况 | G2: 基本信息 | M2: 操作记录 | R2: 交易记录 | V2: 交易笔数 | Z2: 客单价 | AA2: 交易额增长率 | AD2: 同类对比（金额） | AH2: 同类对比（笔数） | AL2: 预警（操作） | AM2: 预警（交易额） | AN2: 预警（交易笔数） | AO2: 最近使用时间 | AP2: 近两周切换未交易 | AQ2: 租户创建时间
G3: 版本 | H3: 诊所类别 | I3: 城市 | J3: 区域 | K3: 店名 | L3: 地址 | M3: 最近一次登录时间 | N3: 最近一次交易时间 | O3: 最近一次门诊时间 | P3: 最近一次药品更新时间 | Q3: 最近一次库存操作时间 | R3: 最近一周 | S3: 最近一月 | T3: 最近三月 | U3: 今年内 | V3: 最近一周 | W3: 最近一月 | X3: 最近三月 | Y3: 今年内 | AA3: 近一个月交易 | AB3: 近两个月交易 | AC3: 近三个月交易 | AD3: 最近一周 | AE3: 最近一月 | AF3: 最近三月 | AG3: 今年内 | AH3: 最近一周 | AI3: 最近一月 | AJ3: 最近三月 | AK3: 今年内
A4: =ROW()-3 -> 1 | B4: =IF(V4=0,"无交易",IF(AND(Y4<=-0.2,Z4<=-0.2,AA4<=-0.2),"连续三月交易下滑",IF(AND(Y4>=0.2,Z4>=0.2,AA4>=0.2),"连续三月交易上升",IF(AND(Y4<0.2,Y4>-0.2,Z4<0.2,Z4>-0.2,AA4<0.2,AA4>-0.2),"交易平稳",IF(OR(ABS(Y4-Z4)>=0.2,ABS(Z4-AA4)>=0.2),"交易波动较大","-"))))) -> 交易波动较大 | C4: =IF(AA4<=-0.5,"本月交易额降超50%",IF(AA4<=-0.2,"本月交易额降超20%","")) | D4: =IF(DATEDIF(AO4,$B$1,"d")>30,"流失",IF(AND(DATEDIF(AO4,$B$1,"d")>7,DATEDIF(AO4,$B$1,"d")<=30),"可能流失",IF(AND(DATEDIF(AO4,$B$1,"d")<=7,DATEDIF(AO4,$B$1,"d")>3),"即将流失","-"))) -> - | E4: 1583731266461929474 | F4: 45043.974 | G4: 正式版 | H4: 中西医诊所 | I4: 四川省成都市 | J4: 龙泉驿区 | K4: 成都万欣公司同生综合门诊部 | L4: 四川省成都市龙泉驿区 | M4: 46104.341 | N4: 46104.398 | O4: 46104.398 | P4: 46101.605 | Q4: 46104.399 | R4: 23899.61 | S4: 120989.01 | T4: 370561.1 | U4: 319500.71 | V4: 102 | W4: 477 | X4: 1503 | Y4: 1322 | Z4: 636.4556 | AA4: -0.020275896 | AB4: -0.020512591 | AC4: -0.29986709 | AD4: =IF(AND($G4="正式版",$H4="中西医诊所"),IFERROR(R4/同类汇总数据!C$3,0),IF(AND($G4="正式版",$H4="中医诊所"),IFERROR(R4/同类汇总数据!C$4,0),IF(AND($G4="正式版",$H4="口腔诊所"),IFERROR(R4/同类汇总数据!C$5,0),IF(AND($G4="检查版",$H4="中西医诊所"),IFERROR(R4/同类汇总数据!C$6,0),IF(AND($G4="检查版",$H4="中医诊所"),IFERROR(R4/同类汇总数据!C$7,0),IF(AND($G4="检查版",$H4="口腔诊所"),IFERROR(R4/同类汇总数据!C$8,0),IF(AND($G4="互联网版",$H4="中西医诊所"),IFERROR(R4/同类汇总数据!C$9,0),IF(AND($G4="互联网版",$H4="中医诊所"),IFERROR(R4/同类汇总数据!C$10,0),IF(AND($G4="互联网版",$H4="口腔诊所"),IFERROR(R4/同类汇总数据!C$11,0)))))))))) -> 2.6114792 | AE4: =IF(AND($G4="正式版",$H4="中西医诊所"),IFERROR(S4/同类汇总数据!D$3,0),IF(AND($G4="正式版",$H4="中医诊所"),IFERROR(S4/同类汇总数据!D$4,0),IF(AND($G4="正式版",$H4="口腔诊所"),IFERROR(S4/同类汇总数据!D$5,0),IF(AND($G4="检查版",$H4="中西医诊所"),IFERROR(S4/同类汇总数据!D$6,0),IF(AND($G4="检查版",$H4="中医诊所"),IFERROR(S4/同类汇总数据!D$7,0),IF(AND($G4="检查版",$H4="口腔诊所"),IFERROR(S4/同类汇总数据!D$8,0),IF(AND($G4="互联网版",$H4="中西医诊所"),IFERROR(S4/同类汇总数据!D$9,0),IF(AND($G4="互联网版",$H4="中医诊所"),IFERROR(S4/同类汇总数据!D$10,0),IF(AND($G4="互联网版",$H4="口腔诊所"),IFERROR(S4/同类汇总数据!D$11,0)))))))))) -> 3.3162479 | AF4: =IF(AND($G4="正式版",$H4="中西医诊所"),IFERROR(T4/同类汇总数据!E$3,0),IF(AND($G4="正式版",$H4="中医诊所"),IFERROR(T4/同类汇总数据!E$4,0),IF(AND($G4="正式版",$H4="口腔诊所"),IFERROR(T4/同类汇总数据!E$5,0),IF(AND($G4="检查版",$H4="中西医诊所"),IFERROR(T4/同类汇总数据!E$6,0),IF(AND($G4="检查版",$H4="中医诊所"),IFERROR(T4/同类汇总数据!E$7,0),IF(AND($G4="检查版",$H4="口腔诊所"),IFERROR(T4/同类汇总数据!E$8,0),IF(AND($G4="互联网版",$H4="中西医诊所"),IFERROR(T4/同类汇总数据!E$9,0),IF(AND($G4="互联网版",$H4="中医诊所"),IFERROR(T4/同类汇总数据!E$10,0),IF(AND($G4="互联网版",$H4="口腔诊所"),IFERROR(T4/同类汇总数据!E$11,0)))))))))) -> 3.3960226 | AG4: =IF(AND($G4="正式版",$H4="中西医诊所"),IFERROR(U4/同类汇总数据!F$3,0),IF(AND($G4="正式版",$H4="中医诊所"),IFERROR(U4/同类汇总数据!F$4,0),IF(AND($G4="正式版",$H4="口腔诊所"),IFERROR(U4/同类汇总数据!F$5,0),IF(AND($G4="检查版",$H4="中西医诊所"),IFERROR(U4/同类汇总数据!F$6,0),IF(AND($G4="检查版",$H4="中医诊所"),IFERROR(U4/同类汇总数据!F$7,0),IF(AND($G4="检查版",$H4="口腔诊所"),IFERROR(U4/同类汇总数据!F$8,0),IF(AND($G4="互联网版",$H4="中西医诊所"),IFERROR(U4/同类汇总数据!F$9,0),IF(AND($G4="互联网版",$H4="中医诊所"),IFERROR(U4/同类汇总数据!F$10,0),IF(AND($G4="互联网版",$H4="口腔诊所"),IFERROR(U4/同类汇总数据!F$11,0)))))))))) -> 3.3307977 | AH4: =IF(AND($G4="正式版",$H4="中西医诊所"),IFERROR(V4/同类汇总数据!G$3,0),IF(AND($G4="正式版",$H4="中医诊所"),IFERROR(V4/同类汇总数据!G$4,0),IF(AND($G4="正式版",$H4="口腔诊所"),IFERROR(V4/同类汇总数据!G$5,0),IF(AND($G4="检查版",$H4="中西医诊所"),IFERROR(V4/同类汇总数据!G$6,0),IF(AND($G4="检查版",$H4="中医诊所"),IFERROR(V4/同类汇总数据!G$7,0),IF(AND($G4="检查版",$H4="口腔诊所"),IFERROR(V4/同类汇总数据!G$8,0),IF(AND($G4="互联网版",$H4="中西医诊所"),IFERROR(V4/同类汇总数据!G$9,0),IF(AND($G4="互联网版",$H4="中医诊所"),IFERROR(V4/同类汇总数据!G$10,0),IF(AND($G4="互联网版",$H4="口腔诊所"),IFERROR(V4/同类汇总数据!G$11,0)))))))))) -> 1.0759369 | AI4: =IF(AND($G4="正式版",$H4="中西医诊所"),IFERROR(W4/同类汇总数据!H$3,0),IF(AND($G4="正式版",$H4="中医诊所"),IFERROR(W4/同类汇总数据!H$4,0),IF(AND($G4="正式版",$H4="口腔诊所"),IFERROR(W4/同类汇总数据!H$5,0),IF(AND($G4="检查版",$H4="中西医诊所"),IFERROR(W4/同类汇总数据!H$6,0),IF(AND($G4="检查版",$H4="中医诊所"),IFERROR(W4/同类汇总数据!H$7,0),IF(AND($G4="检查版",$H4="口腔诊所"),IFERROR(W4/同类汇总数据!H$8,0),IF(AND($G4="互联网版",$H4="中西医诊所"),IFERROR(W4/同类汇总数据!H$9,0),IF(AND($G4="互联网版",$H4="中医诊所"),IFERROR(W4/同类汇总数据!H$10,0),IF(AND($G4="互联网版",$H4="口腔诊所"),IFERROR(W4/同类汇总数据!H$11,0)))))))))) -> 1.3045961 | AJ4: =IF(AND($G4="正式版",$H4="中西医诊所"),IFERROR(X4/同类汇总数据!I$3,0),IF(AND($G4="正式版",$H4="中医诊所"),IFERROR(X4/同类汇总数据!I$4,0),IF(AND($G4="正式版",$H4="口腔诊所"),IFERROR(X4/同类汇总数据!I$5,0),IF(AND($G4="检查版",$H4="中西医诊所"),IFERROR(X4/同类汇总数据!I$6,0),IF(AND($G4="检查版",$H4="中医诊所"),IFERROR(X4/同类汇总数据!I$7,0),IF(AND($G4="检查版",$H4="口腔诊所"),IFERROR(X4/同类汇总数据!I$8,0),IF(AND($G4="互联网版",$H4="中西医诊所"),IFERROR(X4/同类汇总数据!I$9,0),IF(AND($G4="互联网版",$H4="中医诊所"),IFERROR(X4/同类汇总数据!I$10,0),IF(AND($G4="互联网版",$H4="口腔诊所"),IFERROR(X4/同类汇总数据!I$11,0)))))))))) -> 1.3290183 | AK4: =IF(AND($G4="正式版",$H4="中西医诊所"),IFERROR(Y4/同类汇总数据!J$3,0),IF(AND($G4="正式版",$H4="中医诊所"),IFERROR(Y4/同类汇总数据!J$4,0),IF(AND($G4="正式版",$H4="口腔诊所"),IFERROR(Y4/同类汇总数据!J$5,0),IF(AND($G4="检查版",$H4="中西医诊所"),IFERROR(Y4/同类汇总数据!J$6,0),IF(AND($G4="检查版",$H4="中医诊所"),IFERROR(Y4/同类汇总数据!J$7,0),IF(AND($G4="检查版",$H4="口腔诊所"),IFERROR(Y4/同类汇总数据!J$8,0),IF(AND($G4="互联网版",$H4="中西医诊所"),IFERROR(Y4/同类汇总数据!J$9,0),IF(AND($G4="互联网版",$H4="中医诊所"),IFERROR(Y4/同类汇总数据!J$10,0),IF(AND($G4="互联网版",$H4="口腔诊所"),IFERROR(Y4/同类汇总数据!J$11,0)))))))))) -> 1.3209665 | AL4: =IF(YEAR(AO4)<YEAR(TODAY()),"今年内未操作",IF(DATEDIF(AO4,$B$1,"d")>90,"最近三月未操作",IF(DATEDIF(AO4,$B$1,"d")>30,"最近一月未操作",IF(DATEDIF(AO4,$B$1,"d")>7,"最近一周未操作","-")))) -> - | AM4: =IF(AE4<0.2,"低于同行20%",IF(AE4<0.5,"低于同行50%",IF(AE4>=2,"高于同行100%",IF(AE4>=1.5,"高于同行150%",IF(AE4>=1.2,"高于同行20%",""))))) -> 高于同行100% | AN4: =IF(AI4<0.2,"低于同行20%",IF(AI4<0.5,"低于同行50%",IF(AI4>=2,"高于同行100%",IF(AI4>=1.5,"高于同行150%",IF(AI4>=1.2,"高于同行20%",""))))) -> 高于同行20% | AO4: =MAX(IF(M4<>"",M4,0),IF(N4<>"",N4,0),IF(O4<>"",O4,0),IF(P4<>"",P4,0),IF(Q4<>"",Q4,0)) -> 46104.399 | AP4: =IF(AND(DATEDIF(AQ4,$B$1,"d")<=14,DATEDIF(N4,$B$1,"d")>14),"未支付","") | AQ4: 45043.974
A5: =ROW()-3 -> 2 | B5: =IF(V5=0,"无交易",IF(AND(Y5<=-0.2,Z5<=-0.2,AA5<=-0.2),"连续三月交易下滑",IF(AND(Y5>=0.2,Z5>=0.2,AA5>=0.2),"连续三月交易上升",IF(AND(Y5<0.2,Y5>-0.2,Z5<0.2,Z5>-0.2,AA5<0.2,AA5>-0.2),"交易平稳",IF(OR(ABS(Y5-Z5)>=0.2,ABS(Z5-AA5)>=0.2),"交易波动较大","-"))))) -> 连续三月交易上升 | C5: =IF(AA5<=-0.5,"本月交易额降超50%",IF(AA5<=-0.2,"本月交易额降超20%","")) | D5: =IF(DATEDIF(AO5,$B$1,"d")>30,"流失",IF(AND(DATEDIF(AO5,$B$1,"d")>7,DATEDIF(AO5,$B$1,"d")<=30),"可能流失",IF(AND(DATEDIF(AO5,$B$1,"d")<=7,DATEDIF(AO5,$B$1,"d")>3),"即将流失","-"))) -> - | E5: 1591983637474344961 | F5: 45043.974 | G5: 正式版 | H5: 中西医诊所 | I5: 四川省成都市 | J5: 高新区 | K5: 成都高新百康新仁中西医结合诊所有限责任公司 | L5: 四川省成都市高新区 | M5: 46104.336 | N5: 46103.847 | O5: 46103.846 | P5: 46104.354 | Q5: 46104.358 | R5: 17519.74 | S5: 65989.45 | T5: 173107.47 | U5: 154773.22 | V5: 120 | W5: 543 | X5: 1468 | Y5: 1316 | Z5: 227.01794 | AA5: 0.52198958 | AB5: -0.31999826 | AC5: -0.28611732 | AD5: =IF(AND($G5="正式版",$H5="中西医诊所"),IFERROR(R5/同类汇总数据!C$3,0),IF(AND($G5="正式版",$H5="中医诊所"),IFERROR(R5/同类汇总数据!C$4,0),IF(AND($G5="正式版",$H5="口腔诊所"),IFERROR(R5/同类汇总数据!C$5,0),IF(AND($G5="检查版",$H5="中西医诊所"),IFERROR(R5/同类汇总数据!C$6,0),IF(AND($G5="检查版",$H5="中医诊所"),IFERROR(R5/同类汇总数据!C$7,0),IF(AND($G5="检查版",$H5="口腔诊所"),IFERROR(R5/同类汇总数据!C$8,0),IF(AND($G5="互联网版",$H5="中西医诊所"),IFERROR(R5/同类汇总数据!C$9,0),IF(AND($G5="互联网版",$H5="中医诊所"),IFERROR(R5/同类汇总数据!C$10,0),IF(AND($G5="互联网版",$H5="口腔诊所"),IFERROR(R5/同类汇总数据!C$11,0)))))))))) -> 1.9143591 | AE5: =IF(AND($G5="正式版",$H5="中西医诊所"),IFERROR(S5/同类汇总数据!D$3,0),IF(AND($G5="正式版",$H5="中医诊所"),IFERROR(S5/同类汇总数据!D$4,0),IF(AND($G5="正式版",$H5="口腔诊所"),IFERROR(S5/同类汇总数据!D$5,0),IF(AND($G5="检查版",$H5="中西医诊所"),IFERROR(S5/同类汇总数据!D$6,0),IF(AND($G5="检查版",$H5="中医诊所"),IFERROR(S5/同类汇总数据!D$7,0),IF(AND($G5="检查版",$H5="口腔诊所"),IFERROR(S5/同类汇总数据!D$8,0),IF(AND($G5="互联网版",$H5="中西医诊所"),IFERROR(S5/同类汇总数据!D$9,0),IF(AND($G5="互联网版",$H5="中医诊所"),IFERROR(S5/同类汇总数据!D$10,0),IF(AND($G5="互联网版",$H5="口腔诊所"),IFERROR(S5/同类汇总数据!D$11,0)))))))))) -> 1.8087376 | AF5: =IF(AND($G5="正式版",$H5="中西医诊所"),IFERROR(T5/同类汇总数据!E$3,0),IF(AND($G5="正式版",$H5="中医诊所"),IFERROR(T5/同类汇总数据!E$4,0),IF(AND($G5="正式版",$H5="口腔诊所"),IFERROR(T5/同类汇总数据!E$5,0),IF(AND($G5="检查版",$H5="中西医诊所"),IFERROR(T5/同类汇总数据!E$6,0),IF(AND($G5="检查版",$H5="中医诊所"),IFERROR(T5/同类汇总数据!E$7,0),IF(AND($G5="检查版",$H5="口腔诊所"),IFERROR(T5/同类汇总数据!E$8,0),IF(AND($G5="互联网版",$H5="中西医诊所"),IFERROR(T5/同类汇总数据!E$9,0),IF(AND($G5="互联网版",$H5="中医诊所"),IFERROR(T5/同类汇总数据!E$10,0),IF(AND($G5="互联网版",$H5="口腔诊所"),IFERROR(T5/同类汇总数据!E$11,0)))))))))) -> 1.5864506 | AG5: =IF(AND($G5="正式版",$H5="中西医诊所"),IFERROR(U5/同类汇总数据!F$3,0),IF(AND($G5="正式版",$H5="中医诊所"),IFERROR(U5/同类汇总数据!F$4,0),IF(AND($G5="正式版",$H5="口腔诊所"),IFERROR(U5/同类汇总数据!F$5,0),IF(AND($G5="检查版",$H5="中西医诊所"),IFERROR(U5/同类汇总数据!F$6,0),IF(AND($G5="检查版",$H5="中医诊所"),IFERROR(U5/同类汇总数据!F$7,0),IF(AND($G5="检查版",$H5="口腔诊所"),IFERROR(U5/同类汇总数据!F$8,0),IF(AND($G5="互联网版",$H5="中西医诊所"),IFERROR(U5/同类汇总数据!F$9,0),IF(AND($G5="互联网版",$H5="中医诊所"),IFERROR(U5/同类汇总数据!F$10,0),IF(AND($G5="互联网版",$H5="口腔诊所"),IFERROR(U5/同类汇总数据!F$11,0)))))))))) -> 1.6135122 | AH5: =IF(AND($G5="正式版",$H5="中西医诊所"),IFERROR(V5/同类汇总数据!G$3,0),IF(AND($G5="正式版",$H5="中医诊所"),IFERROR(V5/同类汇总数据!G$4,0),IF(AND($G5="正式版",$H5="口腔诊所"),IFERROR(V5/同类汇总数据!G$5,0),IF(AND($G5="检查版",$H5="中西医诊所"),IFERROR(V5/同类汇总数据!G$6,0),IF(AND($G5="检查版",$H5="中医诊所"),IFERROR(V5/同类汇总数据!G$7,0),IF(AND($G5="检查版",$H5="口腔诊所"),IFERROR(V5/同类汇总数据!G$8,0),IF(AND($G5="互联网版",$H5="中西医诊所"),IFERROR(V5/同类汇总数据!G$9,0),IF(AND($G5="互联网版",$H5="中医诊所"),IFERROR(V5/同类汇总数据!G$10,0),IF(AND($G5="互联网版",$H5="口腔诊所"),IFERROR(V5/同类汇总数据!G$11,0)))))))))) -> 1.2658081 | AI5: =IF(AND($G5="正式版",$H5="中西医诊所"),IFERROR(W5/同类汇总数据!H$3,0),IF(AND($G5="正式版",$H5="中医诊所"),IFERROR(W5/同类汇总数据!H$4,0),IF(AND($G5="正式版",$H5="口腔诊所"),IFERROR(W5/同类汇总数据!H$5,0),IF(AND($G5="检查版",$H5="中西医诊所"),IFERROR(W5/同类汇总数据!H$6,0),IF(AND($G5="检查版",$H5="中医诊所"),IFERROR(W5/同类汇总数据!H$7,0),IF(AND($G5="检查版",$H5="口腔诊所"),IFERROR(W5/同类汇总数据!H$8,0),IF(AND($G5="互联网版",$H5="中西医诊所"),IFERROR(W5/同类汇总数据!H$9,0),IF(AND($G5="互联网版",$H5="中医诊所"),IFERROR(W5/同类汇总数据!H$10,0),IF(AND($G5="互联网版",$H5="口腔诊所"),IFERROR(W5/同类汇总数据!H$11,0)))))))))) -> 1.4851063 | AJ5: =IF(AND($G5="正式版",$H5="中西医诊所"),IFERROR(X5/同类汇总数据!I$3,0),IF(AND($G5="正式版",$H5="中医诊所"),IFERROR(X5/同类汇总数据!I$4,0),IF(AND($G5="正式版",$H5="口腔诊所"),IFERROR(X5/同类汇总数据!I$5,0),IF(AND($G5="检查版",$H5="中西医诊所"),IFERROR(X5/同类汇总数据!I$6,0),IF(AND($G5="检查版",$H5="中医诊所"),IFERROR(X5/同类汇总数据!I$7,0),IF(AND($G5="检查版",$H5="口腔诊所"),IFERROR(X5/同类汇总数据!I$8,0),IF(AND($G5="互联网版",$H5="中西医诊所"),IFERROR(X5/同类汇总数据!I$9,0),IF(AND($G5="互联网版",$H5="中医诊所"),IFERROR(X5/同类汇总数据!I$10,0),IF(AND($G5="互联网版",$H5="口腔诊所"),IFERROR(X5/同类汇总数据!I$11,0)))))))))) -> 1.2980698 | AK5: =IF(AND($G5="正式版",$H5="中西医诊所"),IFERROR(Y5/同类汇总数据!J$3,0),IF(AND($G5="正式版",$H5="中医诊所"),IFERROR(Y5/同类汇总数据!J$4,0),IF(AND($G5="正式版",$H5="口腔诊所"),IFERROR(Y5/同类汇总数据!J$5,0),IF(AND($G5="检查版",$H5="中西医诊所"),IFERROR(Y5/同类汇总数据!J$6,0),IF(AND($G5="检查版",$H5="中医诊所"),IFERROR(Y5/同类汇总数据!J$7,0),IF(AND($G5="检查版",$H5="口腔诊所"),IFERROR(Y5/同类汇总数据!J$8,0),IF(AND($G5="互联网版",$H5="中西医诊所"),IFERROR(Y5/同类汇总数据!J$9,0),IF(AND($G5="互联网版",$H5="中医诊所"),IFERROR(Y5/同类汇总数据!J$10,0),IF(AND($G5="互联网版",$H5="口腔诊所"),IFERROR(Y5/同类汇总数据!J$11,0)))))))))) -> 1.3149712 | AL5: =IF(YEAR(AO5)<YEAR(TODAY()),"今年内未操作",IF(DATEDIF(AO5,$B$1,"d")>90,"最近三月未操作",IF(DATEDIF(AO5,$B$1,"d")>30,"最近一月未操作",IF(DATEDIF(AO5,$B$1,"d")>7,"最近一周未操作","-")))) -> - | AM5: =IF(AE5<0.2,"低于同行20%",IF(AE5<0.5,"低于同行50%",IF(AE5>=2,"高于同行100%",IF(AE5>=1.5,"高于同行150%",IF(AE5>=1.2,"高于同行20%",""))))) -> 高于同行150% | AN5: =IF(AI5<0.2,"低于同行20%",IF(AI5<0.5,"低于同行50%",IF(AI5>=2,"高于同行100%",IF(AI5>=1.5,"高于同行150%",IF(AI5>=1.2,"高于同行20%",""))))) -> 高于同行20% | AO5: =MAX(IF(M5<>"",M5,0),IF(N5<>"",N5,0),IF(O5<>"",O5,0),IF(P5<>"",P5,0),IF(Q5<>"",Q5,0)) -> 46104.358 | AP5: =IF(AND(DATEDIF(AQ5,$B$1,"d")<=14,DATEDIF(N5,$B$1,"d")>14),"未支付","") | AQ5: 45043.974
A6: =ROW()-3 -> 3 | B6: =IF(V6=0,"无交易",IF(AND(Y6<=-0.2,Z6<=-0.2,AA6<=-0.2),"连续三月交易下滑",IF(AND(Y6>=0.2,Z6>=0.2,AA6>=0.2),"连续三月交易上升",IF(AND(Y6<0.2,Y6>-0.2,Z6<0.2,Z6>-0.2,AA6<0.2,AA6>-0.2),"交易平稳",IF(OR(ABS(Y6-Z6)>=0.2,ABS(Z6-AA6)>=0.2),"交易波动较大","-"))))) -> 交易波动较大 | C6: =IF(AA6<=-0.5,"本月交易额降超50%",IF(AA6<=-0.2,"本月交易额降超20%","")) | D6: =IF(DATEDIF(AO6,$B$1,"d")>30,"流失",IF(AND(DATEDIF(AO6,$B$1,"d")>7,DATEDIF(AO6,$B$1,"d")<=30),"可能流失",IF(AND(DATEDIF(AO6,$B$1,"d")<=7,DATEDIF(AO6,$B$1,"d")>3),"即将流失","-"))) -> - | E6: 1592351485673644033 | F6: 45043.974 | G6: 正式版 | H6: 中西医诊所 | I6: 四川省成都市 | J6: 龙泉驿区 | K6: 龙泉驿区龙泉街办庆平诊所 | L6: 四川省成都市龙泉驿区 | M6: 46104.32 | N6: 46103.636 | O6: 46103.635 | P6: 46098.809 | Q6: 46103.636 | R6: 7061.42 | S6: 27090.78 | T6: 87166.14 | U6: 76981.99 | V6: 51 | W6: 184 | X6: 593 | Y6: 535 | Z6: 260.07429 | AA6: -0.10098063 | AB6: 0.006413806 | AC6: -0.23680068 | AD6: =IF(AND($G6="正式版",$H6="中西医诊所"),IFERROR(R6/同类汇总数据!C$3,0),IF(AND($G6="正式版",$H6="中医诊所"),IFERROR(R6/同类汇总数据!C$4,0),IF(AND($G6="正式版",$H6="口腔诊所"),IFERROR(R6/同类汇总数据!C$5,0),IF(AND($G6="检查版",$H6="中西医诊所"),IFERROR(R6/同类汇总数据!C$6,0),IF(AND($G6="检查版",$H6="中医诊所"),IFERROR(R6/同类汇总数据!C$7,0),IF(AND($G6="检查版",$H6="口腔诊所"),IFERROR(R6/同类汇总数据!C$8,0),IF(AND($G6="互联网版",$H6="中西医诊所"),IFERROR(R6/同类汇总数据!C$9,0),IF(AND($G6="互联网版",$H6="中医诊所"),IFERROR(R6/同类汇总数据!C$10,0),IF(AND($G6="互联网版",$H6="口腔诊所"),IFERROR(R6/同类汇总数据!C$11,0)))))))))) -> 0.77159215 | AE6: =IF(AND($G6="正式版",$H6="中西医诊所"),IFERROR(S6/同类汇总数据!D$3,0),IF(AND($G6="正式版",$H6="中医诊所"),IFERROR(S6/同类汇总数据!D$4,0),IF(AND($G6="正式版",$H6="口腔诊所"),IFERROR(S6/同类汇总数据!D$5,0),IF(AND($G6="检查版",$H6="中西医诊所"),IFERROR(S6/同类汇总数据!D$6,0),IF(AND($G6="检查版",$H6="中医诊所"),IFERROR(S6/同类汇总数据!D$7,0),IF(AND($G6="检查版",$H6="口腔诊所"),IFERROR(S6/同类汇总数据!D$8,0),IF(AND($G6="互联网版",$H6="中西医诊所"),IFERROR(S6/同类汇总数据!D$9,0),IF(AND($G6="互联网版",$H6="中医诊所"),IFERROR(S6/同类汇总数据!D$10,0),IF(AND($G6="互联网版",$H6="口腔诊所"),IFERROR(S6/同类汇总数据!D$11,0)))))))))) -> 0.74254466 | AF6: =IF(AND($G6="正式版",$H6="中西医诊所"),IFERROR(T6/同类汇总数据!E$3,0),IF(AND($G6="正式版",$H6="中医诊所"),IFERROR(T6/同类汇总数据!E$4,0),IF(AND($G6="正式版",$H6="口腔诊所"),IFERROR(T6/同类汇总数据!E$5,0),IF(AND($G6="检查版",$H6="中西医诊所"),IFERROR(T6/同类汇总数据!E$6,0),IF(AND($G6="检查版",$H6="中医诊所"),IFERROR(T6/同类汇总数据!E$7,0),IF(AND($G6="检查版",$H6="口腔诊所"),IFERROR(T6/同类汇总数据!E$8,0),IF(AND($G6="互联网版",$H6="中西医诊所"),IFERROR(T6/同类汇总数据!E$9,0),IF(AND($G6="互联网版",$H6="中医诊所"),IFERROR(T6/同类汇总数据!E$10,0),IF(AND($G6="互联网版",$H6="口腔诊所"),IFERROR(T6/同类汇总数据!E$11,0)))))))))) -> 0.79883771 | AG6: =IF(AND($G6="正式版",$H6="中西医诊所"),IFERROR(U6/同类汇总数据!F$3,0),IF(AND($G6="正式版",$H6="中医诊所"),IFERROR(U6/同类汇总数据!F$4,0),IF(AND($G6="正式版",$H6="口腔诊所"),IFERROR(U6/同类汇总数据!F$5,0),IF(AND($G6="检查版",$H6="中西医诊所"),IFERROR(U6/同类汇总数据!F$6,0),IF(AND($G6="检查版",$H6="中医诊所"),IFERROR(U6/同类汇总数据!F$7,0),IF(AND($G6="检查版",$H6="口腔诊所"),IFERROR(U6/同类汇总数据!F$8,0),IF(AND($G6="互联网版",$H6="中西医诊所"),IFERROR(U6/同类汇总数据!F$9,0),IF(AND($G6="互联网版",$H6="中医诊所"),IFERROR(U6/同类汇总数据!F$10,0),IF(AND($G6="互联网版",$H6="口腔诊所"),IFERROR(U6/同类汇总数据!F$11,0)))))))))) -> 0.80253793 | AH6: =IF(AND($G6="正式版",$H6="中西医诊所"),IFERROR(V6/同类汇总数据!G$3,0),IF(AND($G6="正式版",$H6="中医诊所"),IFERROR(V6/同类汇总数据!G$4,0),IF(AND($G6="正式版",$H6="口腔诊所"),IFERROR(V6/同类汇总数据!G$5,0),IF(AND($G6="检查版",$H6="中西医诊所"),IFERROR(V6/同类汇总数据!G$6,0),IF(AND($G6="检查版",$H6="中医诊所"),IFERROR(V6/同类汇总数据!G$7,0),IF(AND($G6="检查版",$H6="口腔诊所"),IFERROR(V6/同类汇总数据!G$8,0),IF(AND($G6="互联网版",$H6="中西医诊所"),IFERROR(V6/同类汇总数据!G$9,0),IF(AND($G6="互联网版",$H6="中医诊所"),IFERROR(V6/同类汇总数据!G$10,0),IF(AND($G6="互联网版",$H6="口腔诊所"),IFERROR(V6/同类汇总数据!G$11,0)))))))))) -> 0.53796844 | AI6: =IF(AND($G6="正式版",$H6="中西医诊所"),IFERROR(W6/同类汇总数据!H$3,0),IF(AND($G6="正式版",$H6="中医诊所"),IFERROR(W6/同类汇总数据!H$4,0),IF(AND($G6="正式版",$H6="口腔诊所"),IFERROR(W6/同类汇总数据!H$5,0),IF(AND($G6="检查版",$H6="中西医诊所"),IFERROR(W6/同类汇总数据!H$6,0),IF(AND($G6="检查版",$H6="中医诊所"),IFERROR(W6/同类汇总数据!H$7,0),IF(AND($G6="检查版",$H6="口腔诊所"),IFERROR(W6/同类汇总数据!H$8,0),IF(AND($G6="互联网版",$H6="中西医诊所"),IFERROR(W6/同类汇总数据!H$9,0),IF(AND($G6="互联网版",$H6="中医诊所"),IFERROR(W6/同类汇总数据!H$10,0),IF(AND($G6="互联网版",$H6="口腔诊所"),IFERROR(W6/同类汇总数据!H$11,0)))))))))) -> 0.50324043 | AJ6: =IF(AND($G6="正式版",$H6="中西医诊所"),IFERROR(X6/同类汇总数据!I$3,0),IF(AND($G6="正式版",$H6="中医诊所"),IFERROR(X6/同类汇总数据!I$4,0),IF(AND($G6="正式版",$H6="口腔诊所"),IFERROR(X6/同类汇总数据!I$5,0),IF(AND($G6="检查版",$H6="中西医诊所"),IFERROR(X6/同类汇总数据!I$6,0),IF(AND($G6="检查版",$H6="中医诊所"),IFERROR(X6/同类汇总数据!I$7,0),IF(AND($G6="检查版",$H6="口腔诊所"),IFERROR(X6/同类汇总数据!I$8,0),IF(AND($G6="互联网版",$H6="中西医诊所"),IFERROR(X6/同类汇总数据!I$9,0),IF(AND($G6="互联网版",$H6="中医诊所"),IFERROR(X6/同类汇总数据!I$10,0),IF(AND($G6="互联网版",$H6="口腔诊所"),IFERROR(X6/同类汇总数据!I$11,0)))))))))) -> 0.52435654 | AK6: =IF(AND($G6="正式版",$H6="中西医诊所"),IFERROR(Y6/同类汇总数据!J$3,0),IF(AND($G6="正式版",$H6="中医诊所"),IFERROR(Y6/同类汇总数据!J$4,0),IF(AND($G6="正式版",$H6="口腔诊所"),IFERROR(Y6/同类汇总数据!J$5,0),IF(AND($G6="检查版",$H6="中西医诊所"),IFERROR(Y6/同类汇总数据!J$6,0),IF(AND($G6="检查版",$H6="中医诊所"),IFERROR(Y6/同类汇总数据!J$7,0),IF(AND($G6="检查版",$H6="口腔诊所"),IFERROR(Y6/同类汇总数据!J$8,0),IF(AND($G6="互联网版",$H6="中西医诊所"),IFERROR(Y6/同类汇总数据!J$9,0),IF(AND($G6="互联网版",$H6="中医诊所"),IFERROR(Y6/同类汇总数据!J$10,0),IF(AND($G6="互联网版",$H6="口腔诊所"),IFERROR(Y6/同类汇总数据!J$11,0)))))))))) -> 0.53458174 | AL6: =IF(YEAR(AO6)<YEAR(TODAY()),"今年内未操作",IF(DATEDIF(AO6,$B$1,"d")>90,"最近三月未操作",IF(DATEDIF(AO6,$B$1,"d")>30,"最近一月未操作",IF(DATEDIF(AO6,$B$1,"d")>7,"最近一周未操作","-")))) -> - | AM6: =IF(AE6<0.2,"低于同行20%",IF(AE6<0.5,"低于同行50%",IF(AE6>=2,"高于同行100%",IF(AE6>=1.5,"高于同行150%",IF(AE6>=1.2,"高于同行20%",""))))) | AN6: =IF(AI6<0.2,"低于同行20%",IF(AI6<0.5,"低于同行50%",IF(AI6>=2,"高于同行100%",IF(AI6>=1.5,"高于同行150%",IF(AI6>=1.2,"高于同行20%",""))))) | AO6: =MAX(IF(M6<>"",M6,0),IF(N6<>"",N6,0),IF(O6<>"",O6,0),IF(P6<>"",P6,0),IF(Q6<>"",Q6,0)) -> 46104.32 | AP6: =IF(AND(DATEDIF(AQ6,$B$1,"d")<=14,DATEDIF(N6,$B$1,"d")>14),"未支付","") | AQ6: 45043.974
A7: =ROW()-3 -> 4 | B7: =IF(V7=0,"无交易",IF(AND(Y7<=-0.2,Z7<=-0.2,AA7<=-0.2),"连续三月交易下滑",IF(AND(Y7>=0.2,Z7>=0.2,AA7>=0.2),"连续三月交易上升",IF(AND(Y7<0.2,Y7>-0.2,Z7<0.2,Z7>-0.2,AA7<0.2,AA7>-0.2),"交易平稳",IF(OR(ABS(Y7-Z7)>=0.2,ABS(Z7-AA7)>=0.2),"交易波动较大","-"))))) -> 交易波动较大 | C7: =IF(AA7<=-0.5,"本月交易额降超50%",IF(AA7<=-0.2,"本月交易额降超20%","")) | D7: =IF(DATEDIF(AO7,$B$1,"d")>30,"流失",IF(AND(DATEDIF(AO7,$B$1,"d")>7,DATEDIF(AO7,$B$1,"d")<=30),"可能流失",IF(AND(DATEDIF(AO7,$B$1,"d")<=7,DATEDIF(AO7,$B$1,"d")>3),"即将流失","-"))) -> - | E7: 1592353141383536642 | F7: 45043.974 | G7: 正式版 | H7: 中西医诊所 | I7: 四川省成都市 | J7: 龙泉驿区 | K7: 龙泉驿区十陵街办妙春诊所 | L7: 四川省成都市龙泉驿区 | M7: 46103.331 | N7: 46103.904 | O7: 46102.581 | P7: 45925.389 | Q7: 46103.904 | R7: 2214.2 | S7: 9614.2 | T7: 30303.95 | U7: 25732.1 | V7: 23 | W7: 98 | X7: 303 | Y7: 258 | Z7: 166.95519 | AA7: -0.058479045 | AB7: -0.025485761 | AC7: -0.40824907 | AD7: =IF(AND($G7="正式版",$H7="中西医诊所"),IFERROR(R7/同类汇总数据!C$3,0),IF(AND($G7="正式版",$H7="中医诊所"),IFERROR(R7/同类汇总数据!C$4,0),IF(AND($G7="正式版",$H7="口腔诊所"),IFERROR(R7/同类汇总数据!C$5,0),IF(AND($G7="检查版",$H7="中西医诊所"),IFERROR(R7/同类汇总数据!C$6,0),IF(AND($G7="检查版",$H7="中医诊所"),IFERROR(R7/同类汇总数据!C$7,0),IF(AND($G7="检查版",$H7="口腔诊所"),IFERROR(R7/同类汇总数据!C$8,0),IF(AND($G7="互联网版",$H7="中西医诊所"),IFERROR(R7/同类汇总数据!C$9,0),IF(AND($G7="互联网版",$H7="中医诊所"),IFERROR(R7/同类汇总数据!C$10,0),IF(AND($G7="互联网版",$H7="口腔诊所"),IFERROR(R7/同类汇总数据!C$11,0)))))))))) -> 0.24194274 | AE7: =IF(AND($G7="正式版",$H7="中西医诊所"),IFERROR(S7/同类汇总数据!D$3,0),IF(AND($G7="正式版",$H7="中医诊所"),IFERROR(S7/同类汇总数据!D$4,0),IF(AND($G7="正式版",$H7="口腔诊所"),IFERROR(S7/同类汇总数据!D$5,0),IF(AND($G7="检查版",$H7="中西医诊所"),IFERROR(S7/同类汇总数据!D$6,0),IF(AND($G7="检查版",$H7="中医诊所"),IFERROR(S7/同类汇总数据!D$7,0),IF(AND($G7="检查版",$H7="口腔诊所"),IFERROR(S7/同类汇总数据!D$8,0),IF(AND($G7="互联网版",$H7="中西医诊所"),IFERROR(S7/同类汇总数据!D$9,0),IF(AND($G7="互联网版",$H7="中医诊所"),IFERROR(S7/同类汇总数据!D$10,0),IF(AND($G7="互联网版",$H7="口腔诊所"),IFERROR(S7/同类汇总数据!D$11,0)))))))))) -> 0.26352039 | AF7: =IF(AND($G7="正式版",$H7="中西医诊所"),IFERROR(T7/同类汇总数据!E$3,0),IF(AND($G7="正式版",$H7="中医诊所"),IFERROR(T7/同类汇总数据!E$4,0),IF(AND($G7="正式版",$H7="口腔诊所"),IFERROR(T7/同类汇总数据!E$5,0),IF(AND($G7="检查版",$H7="中西医诊所"),IFERROR(T7/同类汇总数据!E$6,0),IF(AND($G7="检查版",$H7="中医诊所"),IFERROR(T7/同类汇总数据!E$7,0),IF(AND($G7="检查版",$H7="口腔诊所"),IFERROR(T7/同类汇总数据!E$8,0),IF(AND($G7="互联网版",$H7="中西医诊所"),IFERROR(T7/同类汇总数据!E$9,0),IF(AND($G7="互联网版",$H7="中医诊所"),IFERROR(T7/同类汇总数据!E$10,0),IF(AND($G7="互联网版",$H7="口腔诊所"),IFERROR(T7/同类汇总数据!E$11,0)))))))))) -> 0.27772181 | AG7: =IF(AND($G7="正式版",$H7="中西医诊所"),IFERROR(U7/同类汇总数据!F$3,0),IF(AND($G7="正式版",$H7="中医诊所"),IFERROR(U7/同类汇总数据!F$4,0),IF(AND($G7="正式版",$H7="口腔诊所"),IFERROR(U7/同类汇总数据!F$5,0),IF(AND($G7="检查版",$H7="中西医诊所"),IFERROR(U7/同类汇总数据!F$6,0),IF(AND($G7="检查版",$H7="中医诊所"),IFERROR(U7/同类汇总数据!F$7,0),IF(AND($G7="检查版",$H7="口腔诊所"),IFERROR(U7/同类汇总数据!F$8,0),IF(AND($G7="互联网版",$H7="中西医诊所"),IFERROR(U7/同类汇总数据!F$9,0),IF(AND($G7="互联网版",$H7="中医诊所"),IFERROR(U7/同类汇总数据!F$10,0),IF(AND($G7="互联网版",$H7="口腔诊所"),IFERROR(U7/同类汇总数据!F$11,0)))))))))) -> 0.26825737 | AH7: =IF(AND($G7="正式版",$H7="中西医诊所"),IFERROR(V7/同类汇总数据!G$3,0),IF(AND($G7="正式版",$H7="中医诊所"),IFERROR(V7/同类汇总数据!G$4,0),IF(AND($G7="正式版",$H7="口腔诊所"),IFERROR(V7/同类汇总数据!G$5,0),IF(AND($G7="检查版",$H7="中西医诊所"),IFERROR(V7/同类汇总数据!G$6,0),IF(AND($G7="检查版",$H7="中医诊所"),IFERROR(V7/同类汇总数据!G$7,0),IF(AND($G7="检查版",$H7="口腔诊所"),IFERROR(V7/同类汇总数据!G$8,0),IF(AND($G7="互联网版",$H7="中西医诊所"),IFERROR(V7/同类汇总数据!G$9,0),IF(AND($G7="互联网版",$H7="中医诊所"),IFERROR(V7/同类汇总数据!G$10,0),IF(AND($G7="互联网版",$H7="口腔诊所"),IFERROR(V7/同类汇总数据!G$11,0)))))))))) -> 0.24261322 | AI7: =IF(AND($G7="正式版",$H7="中西医诊所"),IFERROR(W7/同类汇总数据!H$3,0),IF(AND($G7="正式版",$H7="中医诊所"),IFERROR(W7/同类汇总数据!H$4,0),IF(AND($G7="正式版",$H7="口腔诊所"),IFERROR(W7/同类汇总数据!H$5,0),IF(AND($G7="检查版",$H7="中西医诊所"),IFERROR(W7/同类汇总数据!H$6,0),IF(AND($G7="检查版",$H7="中医诊所"),IFERROR(W7/同类汇总数据!H$7,0),IF(AND($G7="检查版",$H7="口腔诊所"),IFERROR(W7/同类汇总数据!H$8,0),IF(AND($G7="互联网版",$H7="中西医诊所"),IFERROR(W7/同类汇总数据!H$9,0),IF(AND($G7="互联网版",$H7="中医诊所"),IFERROR(W7/同类汇总数据!H$10,0),IF(AND($G7="互联网版",$H7="口腔诊所"),IFERROR(W7/同类汇总数据!H$11,0)))))))))) -> 0.26803023 | AJ7: =IF(AND($G7="正式版",$H7="中西医诊所"),IFERROR(X7/同类汇总数据!I$3,0),IF(AND($G7="正式版",$H7="中医诊所"),IFERROR(X7/同类汇总数据!I$4,0),IF(AND($G7="正式版",$H7="口腔诊所"),IFERROR(X7/同类汇总数据!I$5,0),IF(AND($G7="检查版",$H7="中西医诊所"),IFERROR(X7/同类汇总数据!I$6,0),IF(AND($G7="检查版",$H7="中医诊所"),IFERROR(X7/同类汇总数据!I$7,0),IF(AND($G7="检查版",$H7="口腔诊所"),IFERROR(X7/同类汇总数据!I$8,0),IF(AND($G7="互联网版",$H7="中西医诊所"),IFERROR(X7/同类汇总数据!I$9,0),IF(AND($G7="互联网版",$H7="中医诊所"),IFERROR(X7/同类汇总数据!I$10,0),IF(AND($G7="互联网版",$H7="口腔诊所"),IFERROR(X7/同类汇总数据!I$11,0)))))))))) -> 0.26792585 | AK7: =IF(AND($G7="正式版",$H7="中西医诊所"),IFERROR(Y7/同类汇总数据!J$3,0),IF(AND($G7="正式版",$H7="中医诊所"),IFERROR(Y7/同类汇总数据!J$4,0),IF(AND($G7="正式版",$H7="口腔诊所"),IFERROR(Y7/同类汇总数据!J$5,0),IF(AND($G7="检查版",$H7="中西医诊所"),IFERROR(Y7/同类汇总数据!J$6,0),IF(AND($G7="检查版",$H7="中医诊所"),IFERROR(Y7/同类汇总数据!J$7,0),IF(AND($G7="检查版",$H7="口腔诊所"),IFERROR(Y7/同类汇总数据!J$8,0),IF(AND($G7="互联网版",$H7="中西医诊所"),IFERROR(Y7/同类汇总数据!J$9,0),IF(AND($G7="互联网版",$H7="中医诊所"),IFERROR(Y7/同类汇总数据!J$10,0),IF(AND($G7="互联网版",$H7="口腔诊所"),IFERROR(Y7/同类汇总数据!J$11,0)))))))))) -> 0.2577983 | AL7: =IF(YEAR(AO7)<YEAR(TODAY()),"今年内未操作",IF(DATEDIF(AO7,$B$1,"d")>90,"最近三月未操作",IF(DATEDIF(AO7,$B$1,"d")>30,"最近一月未操作",IF(DATEDIF(AO7,$B$1,"d")>7,"最近一周未操作","-")))) -> - | AM7: =IF(AE7<0.2,"低于同行20%",IF(AE7<0.5,"低于同行50%",IF(AE7>=2,"高于同行100%",IF(AE7>=1.5,"高于同行150%",IF(AE7>=1.2,"高于同行20%",""))))) -> 低于同行50% | AN7: =IF(AI7<0.2,"低于同行20%",IF(AI7<0.5,"低于同行50%",IF(AI7>=2,"高于同行100%",IF(AI7>=1.5,"高于同行150%",IF(AI7>=1.2,"高于同行20%",""))))) -> 低于同行50% | AO7: =MAX(IF(M7<>"",M7,0),IF(N7<>"",N7,0),IF(O7<>"",O7,0),IF(P7<>"",P7,0),IF(Q7<>"",Q7,0)) -> 46103.904 | AP7: =IF(AND(DATEDIF(AQ7,$B$1,"d")<=14,DATEDIF(N7,$B$1,"d")>14),"未支付","") | AQ7: 45043.974
A8: =ROW()-3 -> 5 | B8: =IF(V8=0,"无交易",IF(AND(Y8<=-0.2,Z8<=-0.2,AA8<=-0.2),"连续三月交易下滑",IF(AND(Y8>=0.2,Z8>=0.2,AA8>=0.2),"连续三月交易上升",IF(AND(Y8<0.2,Y8>-0.2,Z8<0.2,Z8>-0.2,AA8<0.2,AA8>-0.2),"交易平稳",IF(OR(ABS(Y8-Z8)>=0.2,ABS(Z8-AA8)>=0.2),"交易波动较大","-"))))) -> 连续三月交易上升 | C8: =IF(AA8<=-0.5,"本月交易额降超50%",IF(AA8<=-0.2,"本月交易额降超20%","")) | D8: =IF(DATEDIF(AO8,$B$1,"d")>30,"流失",IF(AND(DATEDIF(AO8,$B$1,"d")>7,DATEDIF(AO8,$B$1,"d")<=30),"可能流失",IF(AND(DATEDIF(AO8,$B$1,"d")<=7,DATEDIF(AO8,$B$1,"d")>3),"即将流失","-"))) -> - | E8: 1592405760051290114 | F8: 45043.974 | G8: 正式版 | H8: 中西医诊所 | I8: 四川省成都市 | J8: 双流区 | K8: 双流时康诊所 | L8: 双流西航港大件路白家段998号23幢216号双流时康诊所 | M8: 46103.46 | N8: 46103.604 | O8: 46103.602 | P8: 46094.656 | Q8: 46103.604 | R8: 4760.81 | S8: 20496.89 | T8: 55998.08 | U8: 50133.57 | V8: 20 | W8: 71 | X8: 194 | Y8: 173 | Z8: 534.23194 | AA8: 0.78652494 | AB8: -0.5225161 | AC8: 0.036042675 | AD8: =IF(AND($G8="正式版",$H8="中西医诊所"),IFERROR(R8/同类汇总数据!C$3,0),IF(AND($G8="正式版",$H8="中医诊所"),IFERROR(R8/同类汇总数据!C$4,0),IF(AND($G8="正式版",$H8="口腔诊所"),IFERROR(R8/同类汇总数据!C$5,0),IF(AND($G8="检查版",$H8="中西医诊所"),IFERROR(R8/同类汇总数据!C$6,0),IF(AND($G8="检查版",$H8="中医诊所"),IFERROR(R8/同类汇总数据!C$7,0),IF(AND($G8="检查版",$H8="口腔诊所"),IFERROR(R8/同类汇总数据!C$8,0),IF(AND($G8="互联网版",$H8="中西医诊所"),IFERROR(R8/同类汇总数据!C$9,0),IF(AND($G8="互联网版",$H8="中医诊所"),IFERROR(R8/同类汇总数据!C$10,0),IF(AND($G8="互联网版",$H8="口腔诊所"),IFERROR(R8/同类汇总数据!C$11,0)))))))))) -> 0.5202075 | AE8: =IF(AND($G8="正式版",$H8="中西医诊所"),IFERROR(S8/同类汇总数据!D$3,0),IF(AND($G8="正式版",$H8="中医诊所"),IFERROR(S8/同类汇总数据!D$4,0),IF(AND($G8="正式版",$H8="口腔诊所"),IFERROR(S8/同类汇总数据!D$5,0),IF(AND($G8="检查版",$H8="中西医诊所"),IFERROR(S8/同类汇总数据!D$6,0),IF(AND($G8="检查版",$H8="中医诊所"),IFERROR(S8/同类汇总数据!D$7,0),IF(AND($G8="检查版",$H8="口腔诊所"),IFERROR(S8/同类汇总数据!D$8,0),IF(AND($G8="互联网版",$H8="中西医诊所"),IFERROR(S8/同类汇总数据!D$9,0),IF(AND($G8="互联网版",$H8="中医诊所"),IFERROR(S8/同类汇总数据!D$10,0),IF(AND($G8="互联网版",$H8="口腔诊所"),IFERROR(S8/同类汇总数据!D$11,0)))))))))) -> 0.56180945 | AF8: =IF(AND($G8="正式版",$H8="中西医诊所"),IFERROR(T8/同类汇总数据!E$3,0),IF(AND($G8="正式版",$H8="中医诊所"),IFERROR(T8/同类汇总数据!E$4,0),IF(AND($G8="正式版",$H8="口腔诊所"),IFERROR(T8/同类汇总数据!E$5,0),IF(AND($G8="检查版",$H8="中西医诊所"),IFERROR(T8/同类汇总数据!E$6,0),IF(AND($G8="检查版",$H8="中医诊所"),IFERROR(T8/同类汇总数据!E$7,0),IF(AND($G8="检查版",$H8="口腔诊所"),IFERROR(T8/同类汇总数据!E$8,0),IF(AND($G8="互联网版",$H8="中西医诊所"),IFERROR(T8/同类汇总数据!E$9,0),IF(AND($G8="互联网版",$H8="中医诊所"),IFERROR(T8/同类汇总数据!E$10,0),IF(AND($G8="互联网版",$H8="口腔诊所"),IFERROR(T8/同类汇总数据!E$11,0)))))))))) -> 0.51319673 | AG8: =IF(AND($G8="正式版",$H8="中西医诊所"),IFERROR(U8/同类汇总数据!F$3,0),IF(AND($G8="正式版",$H8="中医诊所"),IFERROR(U8/同类汇总数据!F$4,0),IF(AND($G8="正式版",$H8="口腔诊所"),IFERROR(U8/同类汇总数据!F$5,0),IF(AND($G8="检查版",$H8="中西医诊所"),IFERROR(U8/同类汇总数据!F$6,0),IF(AND($G8="检查版",$H8="中医诊所"),IFERROR(U8/同类汇总数据!F$7,0),IF(AND($G8="检查版",$H8="口腔诊所"),IFERROR(U8/同类汇总数据!F$8,0),IF(AND($G8="互联网版",$H8="中西医诊所"),IFERROR(U8/同类汇总数据!F$9,0),IF(AND($G8="互联网版",$H8="中医诊所"),IFERROR(U8/同类汇总数据!F$10,0),IF(AND($G8="互联网版",$H8="口腔诊所"),IFERROR(U8/同类汇总数据!F$11,0)))))))))) -> 0.52264291 | AH8: =IF(AND($G8="正式版",$H8="中西医诊所"),IFERROR(V8/同类汇总数据!G$3,0),IF(AND($G8="正式版",$H8="中医诊所"),IFERROR(V8/同类汇总数据!G$4,0),IF(AND($G8="正式版",$H8="口腔诊所"),IFERROR(V8/同类汇总数据!G$5,0),IF(AND($G8="检查版",$H8="中西医诊所"),IFERROR(V8/同类汇总数据!G$6,0),IF(AND($G8="检查版",$H8="中医诊所"),IFERROR(V8/同类汇总数据!G$7,0),IF(AND($G8="检查版",$H8="口腔诊所"),IFERROR(V8/同类汇总数据!G$8,0),IF(AND($G8="互联网版",$H8="中西医诊所"),IFERROR(V8/同类汇总数据!G$9,0),IF(AND($G8="互联网版",$H8="中医诊所"),IFERROR(V8/同类汇总数据!G$10,0),IF(AND($G8="互联网版",$H8="口腔诊所"),IFERROR(V8/同类汇总数据!G$11,0)))))))))) -> 0.21096802 | AI8: =IF(AND($G8="正式版",$H8="中西医诊所"),IFERROR(W8/同类汇总数据!H$3,0),IF(AND($G8="正式版",$H8="中医诊所"),IFERROR(W8/同类汇总数据!H$4,0),IF(AND($G8="正式版",$H8="口腔诊所"),IFERROR(W8/同类汇总数据!H$5,0),IF(AND($G8="检查版",$H8="中西医诊所"),IFERROR(W8/同类汇总数据!H$6,0),IF(AND($G8="检查版",$H8="中医诊所"),IFERROR(W8/同类汇总数据!H$7,0),IF(AND($G8="检查版",$H8="口腔诊所"),IFERROR(W8/同类汇总数据!H$8,0),IF(AND($G8="互联网版",$H8="中西医诊所"),IFERROR(W8/同类汇总数据!H$9,0),IF(AND($G8="互联网版",$H8="中医诊所"),IFERROR(W8/同类汇总数据!H$10,0),IF(AND($G8="互联网版",$H8="口腔诊所"),IFERROR(W8/同类汇总数据!H$11,0)))))))))) -> 0.19418517 | AJ8: =IF(AND($G8="正式版",$H8="中西医诊所"),IFERROR(X8/同类汇总数据!I$3,0),IF(AND($G8="正式版",$H8="中医诊所"),IFERROR(X8/同类汇总数据!I$4,0),IF(AND($G8="正式版",$H8="口腔诊所"),IFERROR(X8/同类汇总数据!I$5,0),IF(AND($G8="检查版",$H8="中西医诊所"),IFERROR(X8/同类汇总数据!I$6,0),IF(AND($G8="检查版",$H8="中医诊所"),IFERROR(X8/同类汇总数据!I$7,0),IF(AND($G8="检查版",$H8="口腔诊所"),IFERROR(X8/同类汇总数据!I$8,0),IF(AND($G8="互联网版",$H8="中西医诊所"),IFERROR(X8/同类汇总数据!I$9,0),IF(AND($G8="互联网版",$H8="中医诊所"),IFERROR(X8/同类汇总数据!I$10,0),IF(AND($G8="互联网版",$H8="口腔诊所"),IFERROR(X8/同类汇总数据!I$11,0)))))))))) -> 0.17154329 | AK8: =IF(AND($G8="正式版",$H8="中西医诊所"),IFERROR(Y8/同类汇总数据!J$3,0),IF(AND($G8="正式版",$H8="中医诊所"),IFERROR(Y8/同类汇总数据!J$4,0),IF(AND($G8="正式版",$H8="口腔诊所"),IFERROR(Y8/同类汇总数据!J$5,0),IF(AND($G8="检查版",$H8="中西医诊所"),IFERROR(Y8/同类汇总数据!J$6,0),IF(AND($G8="检查版",$H8="中医诊所"),IFERROR(Y8/同类汇总数据!J$7,0),IF(AND($G8="检查版",$H8="口腔诊所"),IFERROR(Y8/同类汇总数据!J$8,0),IF(AND($G8="互联网版",$H8="中西医诊所"),IFERROR(Y8/同类汇总数据!J$9,0),IF(AND($G8="互联网版",$H8="中医诊所"),IFERROR(Y8/同类汇总数据!J$10,0),IF(AND($G8="互联网版",$H8="口腔诊所"),IFERROR(Y8/同类汇总数据!J$11,0)))))))))) -> 0.17286475 | AL8: =IF(YEAR(AO8)<YEAR(TODAY()),"今年内未操作",IF(DATEDIF(AO8,$B$1,"d")>90,"最近三月未操作",IF(DATEDIF(AO8,$B$1,"d")>30,"最近一月未操作",IF(DATEDIF(AO8,$B$1,"d")>7,"最近一周未操作","-")))) -> - | AM8: =IF(AE8<0.2,"低于同行20%",IF(AE8<0.5,"低于同行50%",IF(AE8>=2,"高于同行100%",IF(AE8>=1.5,"高于同行150%",IF(AE8>=1.2,"高于同行20%",""))))) | AN8: =IF(AI8<0.2,"低于同行20%",IF(AI8<0.5,"低于同行50%",IF(AI8>=2,"高于同行100%",IF(AI8>=1.5,"高于同行150%",IF(AI8>=1.2,"高于同行20%",""))))) -> 低于同行20% | AO8: =MAX(IF(M8<>"",M8,0),IF(N8<>"",N8,0),IF(O8<>"",O8,0),IF(P8<>"",P8,0),IF(Q8<>"",Q8,0)) -> 46103.604 | AP8: =IF(AND(DATEDIF(AQ8,$B$1,"d")<=14,DATEDIF(N8,$B$1,"d")>14),"未支付","") | AQ8: 45043.974
A9: =ROW()-3 -> 6 | B9: =IF(V9=0,"无交易",IF(AND(Y9<=-0.2,Z9<=-0.2,AA9<=-0.2),"连续三月交易下滑",IF(AND(Y9>=0.2,Z9>=0.2,AA9>=0.2),"连续三月交易上升",IF(AND(Y9<0.2,Y9>-0.2,Z9<0.2,Z9>-0.2,AA9<0.2,AA9>-0.2),"交易平稳",IF(OR(ABS(Y9-Z9)>=0.2,ABS(Z9-AA9)>=0.2),"交易波动较大","-"))))) -> 连续三月交易上升 | C9: =IF(AA9<=-0.5,"本月交易额降超50%",IF(AA9<=-0.2,"本月交易额降超20%","")) | D9: =IF(DATEDIF(AO9,$B$1,"d")>30,"流失",IF(AND(DATEDIF(AO9,$B$1,"d")>7,DATEDIF(AO9,$B$1,"d")<=30),"可能流失",IF(AND(DATEDIF(AO9,$B$1,"d")<=7,DATEDIF(AO9,$B$1,"d")>3),"即将流失","-"))) -> - | E9: 1592416195328647169 | F9: 45043.974 | G9: 正式版 | H9: 中西医诊所 | I9: 四川省成都市 | J9: 龙泉驿区 | K9: 龙泉驿吉康诚中西医结合诊所 | L9: 四川省成都市龙泉驿区康阳路1111号13栋103号 | M9: 46104.365 | N9: 46104.397 | O9: 46104.376 | P9: 46102.658 | Q9: 46104.397 | R9: 16364.16 | S9: 60655.65 | T9: 180609.89 | U9: 152920.19 | V9: 305 | W9: 1089 | X9: 3219 | Y9: 2761 | Z9: 116.01063 | AA9: 0.52276096 | AB9: -0.50284692 | AC9: -0.11065019 | AD9: =IF(AND($G9="正式版",$H9="中西医诊所"),IFERROR(R9/同类汇总数据!C$3,0),IF(AND($G9="正式版",$H9="中医诊所"),IFERROR(R9/同类汇总数据!C$4,0),IF(AND($G9="正式版",$H9="口腔诊所"),IFERROR(R9/同类汇总数据!C$5,0),IF(AND($G9="检查版",$H9="中西医诊所"),IFERROR(R9/同类汇总数据!C$6,0),IF(AND($G9="检查版",$H9="中医诊所"),IFERROR(R9/同类汇总数据!C$7,0),IF(AND($G9="检查版",$H9="口腔诊所"),IFERROR(R9/同类汇总数据!C$8,0),IF(AND($G9="互联网版",$H9="中西医诊所"),IFERROR(R9/同类汇总数据!C$9,0),IF(AND($G9="互联网版",$H9="中医诊所"),IFERROR(R9/同类汇总数据!C$10,0),IF(AND($G9="互联网版",$H9="口腔诊所"),IFERROR(R9/同类汇总数据!C$11,0)))))))))) -> 1.7880904 | AE9: =IF(AND($G9="正式版",$H9="中西医诊所"),IFERROR(S9/同类汇总数据!D$3,0),IF(AND($G9="正式版",$H9="中医诊所"),IFERROR(S9/同类汇总数据!D$4,0),IF(AND($G9="正式版",$H9="口腔诊所"),IFERROR(S9/同类汇总数据!D$5,0),IF(AND($G9="检查版",$H9="中西医诊所"),IFERROR(S9/同类汇总数据!D$6,0),IF(AND($G9="检查版",$H9="中医诊所"),IFERROR(S9/同类汇总数据!D$7,0),IF(AND($G9="检查版",$H9="口腔诊所"),IFERROR(S9/同类汇总数据!D$8,0),IF(AND($G9="互联网版",$H9="中西医诊所"),IFERROR(S9/同类汇总数据!D$9,0),IF(AND($G9="互联网版",$H9="中医诊所"),IFERROR(S9/同类汇总数据!D$10,0),IF(AND($G9="互联网版",$H9="口腔诊所"),IFERROR(S9/同类汇总数据!D$11,0)))))))))) -> 1.6625409 | AF9: =IF(AND($G9="正式版",$H9="中西医诊所"),IFERROR(T9/同类汇总数据!E$3,0),IF(AND($G9="正式版",$H9="中医诊所"),IFERROR(T9/同类汇总数据!E$4,0),IF(AND($G9="正式版",$H9="口腔诊所"),IFERROR(T9/同类汇总数据!E$5,0),IF(AND($G9="检查版",$H9="中西医诊所"),IFERROR(T9/同类汇总数据!E$6,0),IF(AND($G9="检查版",$H9="中医诊所"),IFERROR(T9/同类汇总数据!E$7,0),IF(AND($G9="检查版",$H9="口腔诊所"),IFERROR(T9/同类汇总数据!E$8,0),IF(AND($G9="互联网版",$H9="中西医诊所"),IFERROR(T9/同类汇总数据!E$9,0),IF(AND($G9="互联网版",$H9="中医诊所"),IFERROR(T9/同类汇总数据!E$10,0),IF(AND($G9="互联网版",$H9="口腔诊所"),IFERROR(T9/同类汇总数据!E$11,0)))))))))) -> 1.6552068 | AG9: =IF(AND($G9="正式版",$H9="中西医诊所"),IFERROR(U9/同类汇总数据!F$3,0),IF(AND($G9="正式版",$H9="中医诊所"),IFERROR(U9/同类汇总数据!F$4,0),IF(AND($G9="正式版",$H9="口腔诊所"),IFERROR(U9/同类汇总数据!F$5,0),IF(AND($G9="检查版",$H9="中西医诊所"),IFERROR(U9/同类汇总数据!F$6,0),IF(AND($G9="检查版",$H9="中医诊所"),IFERROR(U9/同类汇总数据!F$7,0),IF(AND($G9="检查版",$H9="口腔诊所"),IFERROR(U9/同类汇总数据!F$8,0),IF(AND($G9="互联网版",$H9="中西医诊所"),IFERROR(U9/同类汇总数据!F$9,0),IF(AND($G9="互联网版",$H9="中医诊所"),IFERROR(U9/同类汇总数据!F$10,0),IF(AND($G9="互联网版",$H9="口腔诊所"),IFERROR(U9/同类汇总数据!F$11,0)))))))))) -> 1.5941943 | AH9: =IF(AND($G9="正式版",$H9="中西医诊所"),IFERROR(V9/同类汇总数据!G$3,0),IF(AND($G9="正式版",$H9="中医诊所"),IFERROR(V9/同类汇总数据!G$4,0),IF(AND($G9="正式版",$H9="口腔诊所"),IFERROR(V9/同类汇总数据!G$5,0),IF(AND($G9="检查版",$H9="中西医诊所"),IFERROR(V9/同类汇总数据!G$6,0),IF(AND($G9="检查版",$H9="中医诊所"),IFERROR(V9/同类汇总数据!G$7,0),IF(AND($G9="检查版",$H9="口腔诊所"),IFERROR(V9/同类汇总数据!G$8,0),IF(AND($G9="互联网版",$H9="中西医诊所"),IFERROR(V9/同类汇总数据!G$9,0),IF(AND($G9="互联网版",$H9="中医诊所"),IFERROR(V9/同类汇总数据!G$10,0),IF(AND($G9="互联网版",$H9="口腔诊所"),IFERROR(V9/同类汇总数据!G$11,0)))))))))) -> 3.2172622 | AI9: =IF(AND($G9="正式版",$H9="中西医诊所"),IFERROR(W9/同类汇总数据!H$3,0),IF(AND($G9="正式版",$H9="中医诊所"),IFERROR(W9/同类汇总数据!H$4,0),IF(AND($G9="正式版",$H9="口腔诊所"),IFERROR(W9/同类汇总数据!H$5,0),IF(AND($G9="检查版",$H9="中西医诊所"),IFERROR(W9/同类汇总数据!H$6,0),IF(AND($G9="检查版",$H9="中医诊所"),IFERROR(W9/同类汇总数据!H$7,0),IF(AND($G9="检查版",$H9="口腔诊所"),IFERROR(W9/同类汇总数据!H$8,0),IF(AND($G9="互联网版",$H9="中西医诊所"),IFERROR(W9/同类汇总数据!H$9,0),IF(AND($G9="互联网版",$H9="中医诊所"),IFERROR(W9/同类汇总数据!H$10,0),IF(AND($G9="互联网版",$H9="口腔诊所"),IFERROR(W9/同类汇总数据!H$11,0)))))))))) -> 2.9784175 | AJ9: =IF(AND($G9="正式版",$H9="中西医诊所"),IFERROR(X9/同类汇总数据!I$3,0),IF(AND($G9="正式版",$H9="中医诊所"),IFERROR(X9/同类汇总数据!I$4,0),IF(AND($G9="正式版",$H9="口腔诊所"),IFERROR(X9/同类汇总数据!I$5,0),IF(AND($G9="检查版",$H9="中西医诊所"),IFERROR(X9/同类汇总数据!I$6,0),IF(AND($G9="检查版",$H9="中医诊所"),IFERROR(X9/同类汇总数据!I$7,0),IF(AND($G9="检查版",$H9="口腔诊所"),IFERROR(X9/同类汇总数据!I$8,0),IF(AND($G9="互联网版",$H9="中西医诊所"),IFERROR(X9/同类汇总数据!I$9,0),IF(AND($G9="互联网版",$H9="中医诊所"),IFERROR(X9/同类汇总数据!I$10,0),IF(AND($G9="互联网版",$H9="口腔诊所"),IFERROR(X9/同类汇总数据!I$11,0)))))))))) -> 2.8463806 | AK9: =IF(AND($G9="正式版",$H9="中西医诊所"),IFERROR(Y9/同类汇总数据!J$3,0),IF(AND($G9="正式版",$H9="中医诊所"),IFERROR(Y9/同类汇总数据!J$4,0),IF(AND($G9="正式版",$H9="口腔诊所"),IFERROR(Y9/同类汇总数据!J$5,0),IF(AND($G9="检查版",$H9="中西医诊所"),IFERROR(Y9/同类汇总数据!J$6,0),IF(AND($G9="检查版",$H9="中医诊所"),IFERROR(Y9/同类汇总数据!J$7,0),IF(AND($G9="检查版",$H9="口腔诊所"),IFERROR(Y9/同类汇总数据!J$8,0),IF(AND($G9="互联网版",$H9="中西医诊所"),IFERROR(Y9/同类汇总数据!J$9,0),IF(AND($G9="互联网版",$H9="中医诊所"),IFERROR(Y9/同类汇总数据!J$10,0),IF(AND($G9="互联网版",$H9="口腔诊所"),IFERROR(Y9/同类汇总数据!J$11,0)))))))))) -> 2.7588415 | AL9: =IF(YEAR(AO9)<YEAR(TODAY()),"今年内未操作",IF(DATEDIF(AO9,$B$1,"d")>90,"最近三月未操作",IF(DATEDIF(AO9,$B$1,"d")>30,"最近一月未操作",IF(DATEDIF(AO9,$B$1,"d")>7,"最近一周未操作","-")))) -> - | AM9: =IF(AE9<0.2,"低于同行20%",IF(AE9<0.5,"低于同行50%",IF(AE9>=2,"高于同行100%",IF(AE9>=1.5,"高于同行150%",IF(AE9>=1.2,"高于同行20%",""))))) -> 高于同行150% | AN9: =IF(AI9<0.2,"低于同行20%",IF(AI9<0.5,"低于同行50%",IF(AI9>=2,"高于同行100%",IF(AI9>=1.5,"高于同行150%",IF(AI9>=1.2,"高于同行20%",""))))) -> 高于同行100% | AO9: =MAX(IF(M9<>"",M9,0),IF(N9<>"",N9,0),IF(O9<>"",O9,0),IF(P9<>"",P9,0),IF(Q9<>"",Q9,0)) -> 46104.397 | AP9: =IF(AND(DATEDIF(AQ9,$B$1,"d")<=14,DATEDIF(N9,$B$1,"d")>14),"未支付","") | AQ9: 45043.974
A10: =ROW()-3 -> 7 | B10: =IF(V10=0,"无交易",IF(AND(Y10<=-0.2,Z10<=-0.2,AA10<=-0.2),"连续三月交易下滑",IF(AND(Y10>=0.2,Z10>=0.2,AA10>=0.2),"连续三月交易上升",IF(AND(Y10<0.2,Y10>-0.2,Z10<0.2,Z10>-0.2,AA10<0.2,AA10>-0.2),"交易平稳",IF(OR(ABS(Y10-Z10)>=0.2,ABS(Z10-AA10)>=0.2),"交易波动较大","-"))))) -> 无交易 | C10: =IF(AA10<=-0.5,"本月交易额降超50%",IF(AA10<=-0.2,"本月交易额降超20%","")) | D10: =IF(DATEDIF(AO10,$B$1,"d")>30,"流失",IF(AND(DATEDIF(AO10,$B$1,"d")>7,DATEDIF(AO10,$B$1,"d")<=30),"可能流失",IF(AND(DATEDIF(AO10,$B$1,"d")<=7,DATEDIF(AO10,$B$1,"d")>3),"即将流失","-"))) -> 流失 | E10: 1593175224812371969 | F10: 45043.974 | G10: 检查版 | H10: 中西医诊所 | I10: 四川省成都市 | J10: 高新区 | K10: 成都高新谦康中西医结合诊所有限责任公司 | L10: 四川省成都市高新区 | M10: 45456.393 | P10: 45456.53 | AD10: =IF(AND($G10="正式版",$H10="中西医诊所"),IFERROR(R10/同类汇总数据!C$3,0),IF(AND($G10="正式版",$H10="中医诊所"),IFERROR(R10/同类汇总数据!C$4,0),IF(AND($G10="正式版",$H10="口腔诊所"),IFERROR(R10/同类汇总数据!C$5,0),IF(AND($G10="检查版",$H10="中西医诊所"),IFERROR(R10/同类汇总数据!C$6,0),IF(AND($G10="检查版",$H10="中医诊所"),IFERROR(R10/同类汇总数据!C$7,0),IF(AND($G10="检查版",$H10="口腔诊所"),IFERROR(R10/同类汇总数据!C$8,0),IF(AND($G10="互联网版",$H10="中西医诊所"),IFERROR(R10/同类汇总数据!C$9,0),IF(AND($G10="互联网版",$H10="中医诊所"),IFERROR(R10/同类汇总数据!C$10,0),IF(AND($G10="互联网版",$H10="口腔诊所"),IFERROR(R10/同类汇总数据!C$11,0)))))))))) -> 0 | AE10: =IF(AND($G10="正式版",$H10="中西医诊所"),IFERROR(S10/同类汇总数据!D$3,0),IF(AND($G10="正式版",$H10="中医诊所"),IFERROR(S10/同类汇总数据!D$4,0),IF(AND($G10="正式版",$H10="口腔诊所"),IFERROR(S10/同类汇总数据!D$5,0),IF(AND($G10="检查版",$H10="中西医诊所"),IFERROR(S10/同类汇总数据!D$6,0),IF(AND($G10="检查版",$H10="中医诊所"),IFERROR(S10/同类汇总数据!D$7,0),IF(AND($G10="检查版",$H10="口腔诊所"),IFERROR(S10/同类汇总数据!D$8,0),IF(AND($G10="互联网版",$H10="中西医诊所"),IFERROR(S10/同类汇总数据!D$9,0),IF(AND($G10="互联网版",$H10="中医诊所"),IFERROR(S10/同类汇总数据!D$10,0),IF(AND($G10="互联网版",$H10="口腔诊所"),IFERROR(S10/同类汇总数据!D$11,0)))))))))) -> 0 | AF10: =IF(AND($G10="正式版",$H10="中西医诊所"),IFERROR(T10/同类汇总数据!E$3,0),IF(AND($G10="正式版",$H10="中医诊所"),IFERROR(T10/同类汇总数据!E$4,0),IF(AND($G10="正式版",$H10="口腔诊所"),IFERROR(T10/同类汇总数据!E$5,0),IF(AND($G10="检查版",$H10="中西医诊所"),IFERROR(T10/同类汇总数据!E$6,0),IF(AND($G10="检查版",$H10="中医诊所"),IFERROR(T10/同类汇总数据!E$7,0),IF(AND($G10="检查版",$H10="口腔诊所"),IFERROR(T10/同类汇总数据!E$8,0),IF(AND($G10="互联网版",$H10="中西医诊所"),IFERROR(T10/同类汇总数据!E$9,0),IF(AND($G10="互联网版",$H10="中医诊所"),IFERROR(T10/同类汇总数据!E$10,0),IF(AND($G10="互联网版",$H10="口腔诊所"),IFERROR(T10/同类汇总数据!E$11,0)))))))))) -> 0 | AG10: =IF(AND($G10="正式版",$H10="中西医诊所"),IFERROR(U10/同类汇总数据!F$3,0),IF(AND($G10="正式版",$H10="中医诊所"),IFERROR(U10/同类汇总数据!F$4,0),IF(AND($G10="正式版",$H10="口腔诊所"),IFERROR(U10/同类汇总数据!F$5,0),IF(AND($G10="检查版",$H10="中西医诊所"),IFERROR(U10/同类汇总数据!F$6,0),IF(AND($G10="检查版",$H10="中医诊所"),IFERROR(U10/同类汇总数据!F$7,0),IF(AND($G10="检查版",$H10="口腔诊所"),IFERROR(U10/同类汇总数据!F$8,0),IF(AND($G10="互联网版",$H10="中西医诊所"),IFERROR(U10/同类汇总数据!F$9,0),IF(AND($G10="互联网版",$H10="中医诊所"),IFERROR(U10/同类汇总数据!F$10,0),IF(AND($G10="互联网版",$H10="口腔诊所"),IFERROR(U10/同类汇总数据!F$11,0)))))))))) -> 0 | AH10: =IF(AND($G10="正式版",$H10="中西医诊所"),IFERROR(V10/同类汇总数据!G$3,0),IF(AND($G10="正式版",$H10="中医诊所"),IFERROR(V10/同类汇总数据!G$4,0),IF(AND($G10="正式版",$H10="口腔诊所"),IFERROR(V10/同类汇总数据!G$5,0),IF(AND($G10="检查版",$H10="中西医诊所"),IFERROR(V10/同类汇总数据!G$6,0),IF(AND($G10="检查版",$H10="中医诊所"),IFERROR(V10/同类汇总数据!G$7,0),IF(AND($G10="检查版",$H10="口腔诊所"),IFERROR(V10/同类汇总数据!G$8,0),IF(AND($G10="互联网版",$H10="中西医诊所"),IFERROR(V10/同类汇总数据!G$9,0),IF(AND($G10="互联网版",$H10="中医诊所"),IFERROR(V10/同类汇总数据!G$10,0),IF(AND($G10="互联网版",$H10="口腔诊所"),IFERROR(V10/同类汇总数据!G$11,0)))))))))) -> 0 | AI10: =IF(AND($G10="正式版",$H10="中西医诊所"),IFERROR(W10/同类汇总数据!H$3,0),IF(AND($G10="正式版",$H10="中医诊所"),IFERROR(W10/同类汇总数据!H$4,0),IF(AND($G10="正式版",$H10="口腔诊所"),IFERROR(W10/同类汇总数据!H$5,0),IF(AND($G10="检查版",$H10="中西医诊所"),IFERROR(W10/同类汇总数据!H$6,0),IF(AND($G10="检查版",$H10="中医诊所"),IFERROR(W10/同类汇总数据!H$7,0),IF(AND($G10="检查版",$H10="口腔诊所"),IFERROR(W10/同类汇总数据!H$8,0),IF(AND($G10="互联网版",$H10="中西医诊所"),IFERROR(W10/同类汇总数据!H$9,0),IF(AND($G10="互联网版",$H10="中医诊所"),IFERROR(W10/同类汇总数据!H$10,0),IF(AND($G10="互联网版",$H10="口腔诊所"),IFERROR(W10/同类汇总数据!H$11,0)))))))))) -> 0 | AJ10: =IF(AND($G10="正式版",$H10="中西医诊所"),IFERROR(X10/同类汇总数据!I$3,0),IF(AND($G10="正式版",$H10="中医诊所"),IFERROR(X10/同类汇总数据!I$4,0),IF(AND($G10="正式版",$H10="口腔诊所"),IFERROR(X10/同类汇总数据!I$5,0),IF(AND($G10="检查版",$H10="中西医诊所"),IFERROR(X10/同类汇总数据!I$6,0),IF(AND($G10="检查版",$H10="中医诊所"),IFERROR(X10/同类汇总数据!I$7,0),IF(AND($G10="检查版",$H10="口腔诊所"),IFERROR(X10/同类汇总数据!I$8,0),IF(AND($G10="互联网版",$H10="中西医诊所"),IFERROR(X10/同类汇总数据!I$9,0),IF(AND($G10="互联网版",$H10="中医诊所"),IFERROR(X10/同类汇总数据!I$10,0),IF(AND($G10="互联网版",$H10="口腔诊所"),IFERROR(X10/同类汇总数据!I$11,0)))))))))) -> 0 | AK10: =IF(AND($G10="正式版",$H10="中西医诊所"),IFERROR(Y10/同类汇总数据!J$3,0),IF(AND($G10="正式版",$H10="中医诊所"),IFERROR(Y10/同类汇总数据!J$4,0),IF(AND($G10="正式版",$H10="口腔诊所"),IFERROR(Y10/同类汇总数据!J$5,0),IF(AND($G10="检查版",$H10="中西医诊所"),IFERROR(Y10/同类汇总数据!J$6,0),IF(AND($G10="检查版",$H10="中医诊所"),IFERROR(Y10/同类汇总数据!J$7,0),IF(AND($G10="检查版",$H10="口腔诊所"),IFERROR(Y10/同类汇总数据!J$8,0),IF(AND($G10="互联网版",$H10="中西医诊所"),IFERROR(Y10/同类汇总数据!J$9,0),IF(AND($G10="互联网版",$H10="中医诊所"),IFERROR(Y10/同类汇总数据!J$10,0),IF(AND($G10="互联网版",$H10="口腔诊所"),IFERROR(Y10/同类汇总数据!J$11,0)))))))))) -> 0 | AL10: =IF(YEAR(AO10)<YEAR(TODAY()),"今年内未操作",IF(DATEDIF(AO10,$B$1,"d")>90,"最近三月未操作",IF(DATEDIF(AO10,$B$1,"d")>30,"最近一月未操作",IF(DATEDIF(AO10,$B$1,"d")>7,"最近一周未操作","-")))) -> 今年内未操作 | AM10: =IF(AE10<0.2,"低于同行20%",IF(AE10<0.5,"低于同行50%",IF(AE10>=2,"高于同行100%",IF(AE10>=1.5,"高于同行150%",IF(AE10>=1.2,"高于同行20%",""))))) -> 低于同行20% | AN10: =IF(AI10<0.2,"低于同行20%",IF(AI10<0.5,"低于同行50%",IF(AI10>=2,"高于同行100%",IF(AI10>=1.5,"高于同行150%",IF(AI10>=1.2,"高于同行20%",""))))) -> 低于同行20% | AO10: =MAX(IF(M10<>"",M10,0),IF(N10<>"",N10,0),IF(O10<>"",O10,0),IF(P10<>"",P10,0),IF(Q10<>"",Q10,0)) -> 45456.53 | AP10: =IF(AND(DATEDIF(AQ10,$B$1,"d")<=14,DATEDIF(N10,$B$1,"d")>14),"未支付","") | AQ10: 45043.974
A11: =ROW()-3 -> 8 | B11: =IF(V11=0,"无交易",IF(AND(Y11<=-0.2,Z11<=-0.2,AA11<=-0.2),"连续三月交易下滑",IF(AND(Y11>=0.2,Z11>=0.2,AA11>=0.2),"连续三月交易上升",IF(AND(Y11<0.2,Y11>-0.2,Z11<0.2,Z11>-0.2,AA11<0.2,AA11>-0.2),"交易平稳",IF(OR(ABS(Y11-Z11)>=0.2,ABS(Z11-AA11)>=0.2),"交易波动较大","-"))))) -> 无交易 | C11: =IF(AA11<=-0.5,"本月交易额降超50%",IF(AA11<=-0.2,"本月交易额降超20%","")) | D11: =IF(DATEDIF(AO11,$B$1,"d")>30,"流失",IF(AND(DATEDIF(AO11,$B$1,"d")>7,DATEDIF(AO11,$B$1,"d")<=30),"可能流失",IF(AND(DATEDIF(AO11,$B$1,"d")<=7,DATEDIF(AO11,$B$1,"d")>3),"即将流失","-"))) -> 流失 | E11: 1593177936950001665 | F11: 45043.974 | G11: 检查版 | H11: 口腔诊所 | I11: 四川省成都市 | J11: 高新区 | K11: 成都高新谦谦口腔诊所有限责任公司 | L11: 四川省成都市高新区 | M11: 45268.735 | P11: 45172.383 | AD11: =IF(AND($G11="正式版",$H11="中西医诊所"),IFERROR(R11/同类汇总数据!C$3,0),IF(AND($G11="正式版",$H11="中医诊所"),IFERROR(R11/同类汇总数据!C$4,0),IF(AND($G11="正式版",$H11="口腔诊所"),IFERROR(R11/同类汇总数据!C$5,0),IF(AND($G11="检查版",$H11="中西医诊所"),IFERROR(R11/同类汇总数据!C$6,0),IF(AND($G11="检查版",$H11="中医诊所"),IFERROR(R11/同类汇总数据!C$7,0),IF(AND($G11="检查版",$H11="口腔诊所"),IFERROR(R11/同类汇总数据!C$8,0),IF(AND($G11="互联网版",$H11="中西医诊所"),IFERROR(R11/同类汇总数据!C$9,0),IF(AND($G11="互联网版",$H11="中医诊所"),IFERROR(R11/同类汇总数据!C$10,0),IF(AND($G11="互联网版",$H11="口腔诊所"),IFERROR(R11/同类汇总数据!C$11,0)))))))))) -> 0 | AE11: =IF(AND($G11="正式版",$H11="中西医诊所"),IFERROR(S11/同类汇总数据!D$3,0),IF(AND($G11="正式版",$H11="中医诊所"),IFERROR(S11/同类汇总数据!D$4,0),IF(AND($G11="正式版",$H11="口腔诊所"),IFERROR(S11/同类汇总数据!D$5,0),IF(AND($G11="检查版",$H11="中西医诊所"),IFERROR(S11/同类汇总数据!D$6,0),IF(AND($G11="检查版",$H11="中医诊所"),IFERROR(S11/同类汇总数据!D$7,0),IF(AND($G11="检查版",$H11="口腔诊所"),IFERROR(S11/同类汇总数据!D$8,0),IF(AND($G11="互联网版",$H11="中西医诊所"),IFERROR(S11/同类汇总数据!D$9,0),IF(AND($G11="互联网版",$H11="中医诊所"),IFERROR(S11/同类汇总数据!D$10,0),IF(AND($G11="互联网版",$H11="口腔诊所"),IFERROR(S11/同类汇总数据!D$11,0)))))))))) -> 0 | AF11: =IF(AND($G11="正式版",$H11="中西医诊所"),IFERROR(T11/同类汇总数据!E$3,0),IF(AND($G11="正式版",$H11="中医诊所"),IFERROR(T11/同类汇总数据!E$4,0),IF(AND($G11="正式版",$H11="口腔诊所"),IFERROR(T11/同类汇总数据!E$5,0),IF(AND($G11="检查版",$H11="中西医诊所"),IFERROR(T11/同类汇总数据!E$6,0),IF(AND($G11="检查版",$H11="中医诊所"),IFERROR(T11/同类汇总数据!E$7,0),IF(AND($G11="检查版",$H11="口腔诊所"),IFERROR(T11/同类汇总数据!E$8,0),IF(AND($G11="互联网版",$H11="中西医诊所"),IFERROR(T11/同类汇总数据!E$9,0),IF(AND($G11="互联网版",$H11="中医诊所"),IFERROR(T11/同类汇总数据!E$10,0),IF(AND($G11="互联网版",$H11="口腔诊所"),IFERROR(T11/同类汇总数据!E$11,0)))))))))) -> 0 | AG11: =IF(AND($G11="正式版",$H11="中西医诊所"),IFERROR(U11/同类汇总数据!F$3,0),IF(AND($G11="正式版",$H11="中医诊所"),IFERROR(U11/同类汇总数据!F$4,0),IF(AND($G11="正式版",$H11="口腔诊所"),IFERROR(U11/同类汇总数据!F$5,0),IF(AND($G11="检查版",$H11="中西医诊所"),IFERROR(U11/同类汇总数据!F$6,0),IF(AND($G11="检查版",$H11="中医诊所"),IFERROR(U11/同类汇总数据!F$7,0),IF(AND($G11="检查版",$H11="口腔诊所"),IFERROR(U11/同类汇总数据!F$8,0),IF(AND($G11="互联网版",$H11="中西医诊所"),IFERROR(U11/同类汇总数据!F$9,0),IF(AND($G11="互联网版",$H11="中医诊所"),IFERROR(U11/同类汇总数据!F$10,0),IF(AND($G11="互联网版",$H11="口腔诊所"),IFERROR(U11/同类汇总数据!F$11,0)))))))))) -> 0 | AH11: =IF(AND($G11="正式版",$H11="中西医诊所"),IFERROR(V11/同类汇总数据!G$3,0),IF(AND($G11="正式版",$H11="中医诊所"),IFERROR(V11/同类汇总数据!G$4,0),IF(AND($G11="正式版",$H11="口腔诊所"),IFERROR(V11/同类汇总数据!G$5,0),IF(AND($G11="检查版",$H11="中西医诊所"),IFERROR(V11/同类汇总数据!G$6,0),IF(AND($G11="检查版",$H11="中医诊所"),IFERROR(V11/同类汇总数据!G$7,0),IF(AND($G11="检查版",$H11="口腔诊所"),IFERROR(V11/同类汇总数据!G$8,0),IF(AND($G11="互联网版",$H11="中西医诊所"),IFERROR(V11/同类汇总数据!G$9,0),IF(AND($G11="互联网版",$H11="中医诊所"),IFERROR(V11/同类汇总数据!G$10,0),IF(AND($G11="互联网版",$H11="口腔诊所"),IFERROR(V11/同类汇总数据!G$11,0)))))))))) -> 0 | AI11: =IF(AND($G11="正式版",$H11="中西医诊所"),IFERROR(W11/同类汇总数据!H$3,0),IF(AND($G11="正式版",$H11="中医诊所"),IFERROR(W11/同类汇总数据!H$4,0),IF(AND($G11="正式版",$H11="口腔诊所"),IFERROR(W11/同类汇总数据!H$5,0),IF(AND($G11="检查版",$H11="中西医诊所"),IFERROR(W11/同类汇总数据!H$6,0),IF(AND($G11="检查版",$H11="中医诊所"),IFERROR(W11/同类汇总数据!H$7,0),IF(AND($G11="检查版",$H11="口腔诊所"),IFERROR(W11/同类汇总数据!H$8,0),IF(AND($G11="互联网版",$H11="中西医诊所"),IFERROR(W11/同类汇总数据!H$9,0),IF(AND($G11="互联网版",$H11="中医诊所"),IFERROR(W11/同类汇总数据!H$10,0),IF(AND($G11="互联网版",$H11="口腔诊所"),IFERROR(W11/同类汇总数据!H$11,0)))))))))) -> 0 | AJ11: =IF(AND($G11="正式版",$H11="中西医诊所"),IFERROR(X11/同类汇总数据!I$3,0),IF(AND($G11="正式版",$H11="中医诊所"),IFERROR(X11/同类汇总数据!I$4,0),IF(AND($G11="正式版",$H11="口腔诊所"),IFERROR(X11/同类汇总数据!I$5,0),IF(AND($G11="检查版",$H11="中西医诊所"),IFERROR(X11/同类汇总数据!I$6,0),IF(AND($G11="检查版",$H11="中医诊所"),IFERROR(X11/同类汇总数据!I$7,0),IF(AND($G11="检查版",$H11="口腔诊所"),IFERROR(X11/同类汇总数据!I$8,0),IF(AND($G11="互联网版",$H11="中西医诊所"),IFERROR(X11/同类汇总数据!I$9,0),IF(AND($G11="互联网版",$H11="中医诊所"),IFERROR(X11/同类汇总数据!I$10,0),IF(AND($G11="互联网版",$H11="口腔诊所"),IFERROR(X11/同类汇总数据!I$11,0)))))))))) -> 0 | AK11: =IF(AND($G11="正式版",$H11="中西医诊所"),IFERROR(Y11/同类汇总数据!J$3,0),IF(AND($G11="正式版",$H11="中医诊所"),IFERROR(Y11/同类汇总数据!J$4,0),IF(AND($G11="正式版",$H11="口腔诊所"),IFERROR(Y11/同类汇总数据!J$5,0),IF(AND($G11="检查版",$H11="中西医诊所"),IFERROR(Y11/同类汇总数据!J$6,0),IF(AND($G11="检查版",$H11="中医诊所"),IFERROR(Y11/同类汇总数据!J$7,0),IF(AND($G11="检查版",$H11="口腔诊所"),IFERROR(Y11/同类汇总数据!J$8,0),IF(AND($G11="互联网版",$H11="中西医诊所"),IFERROR(Y11/同类汇总数据!J$9,0),IF(AND($G11="互联网版",$H11="中医诊所"),IFERROR(Y11/同类汇总数据!J$10,0),IF(AND($G11="互联网版",$H11="口腔诊所"),IFERROR(Y11/同类汇总数据!J$11,0)))))))))) -> 0 | AL11: =IF(YEAR(AO11)<YEAR(TODAY()),"今年内未操作",IF(DATEDIF(AO11,$B$1,"d")>90,"最近三月未操作",IF(DATEDIF(AO11,$B$1,"d")>30,"最近一月未操作",IF(DATEDIF(AO11,$B$1,"d")>7,"最近一周未操作","-")))) -> 今年内未操作 | AM11: =IF(AE11<0.2,"低于同行20%",IF(AE11<0.5,"低于同行50%",IF(AE11>=2,"高于同行100%",IF(AE11>=1.5,"高于同行150%",IF(AE11>=1.2,"高于同行20%",""))))) -> 低于同行20% | AN11: =IF(AI11<0.2,"低于同行20%",IF(AI11<0.5,"低于同行50%",IF(AI11>=2,"高于同行100%",IF(AI11>=1.5,"高于同行150%",IF(AI11>=1.2,"高于同行20%",""))))) -> 低于同行20% | AO11: =MAX(IF(M11<>"",M11,0),IF(N11<>"",N11,0),IF(O11<>"",O11,0),IF(P11<>"",P11,0),IF(Q11<>"",Q11,0)) -> 45268.735 | AP11: =IF(AND(DATEDIF(AQ11,$B$1,"d")<=14,DATEDIF(N11,$B$1,"d")>14),"未支付","") | AQ11: 45043.974
A12: =ROW()-3 -> 9 | B12: =IF(V12=0,"无交易",IF(AND(Y12<=-0.2,Z12<=-0.2,AA12<=-0.2),"连续三月交易下滑",IF(AND(Y12>=0.2,Z12>=0.2,AA12>=0.2),"连续三月交易上升",IF(AND(Y12<0.2,Y12>-0.2,Z12<0.2,Z12>-0.2,AA12<0.2,AA12>-0.2),"交易平稳",IF(OR(ABS(Y12-Z12)>=0.2,ABS(Z12-AA12)>=0.2),"交易波动较大","-"))))) -> 连续三月交易上升 | C12: =IF(AA12<=-0.5,"本月交易额降超50%",IF(AA12<=-0.2,"本月交易额降超20%","")) | D12: =IF(DATEDIF(AO12,$B$1,"d")>30,"流失",IF(AND(DATEDIF(AO12,$B$1,"d")>7,DATEDIF(AO12,$B$1,"d")<=30),"可能流失",IF(AND(DATEDIF(AO12,$B$1,"d")<=7,DATEDIF(AO12,$B$1,"d")>3),"即将流失","-"))) -> - | E12: 1595041171678490625 | F12: 45043.974 | G12: 正式版 | H12: 中医诊所 | I12: 四川省成都市 | J12: 新津县 | K12: 成都市新津求实中医诊所有限公司 | M12: 46104.356 | N12: 46104.392 | O12: 46104.4 | P12: 46099.467 | Q12: 46104.392 | R12: 46493.82 | S12: 181495.73 | T12: 504568.96 | U12: 450884.83 | V12: 294 | W12: 1246 | X12: 3468 | Y12: 3132 | Z12: 322.06059 | AA12: 0.36022722 | AB12: -0.29641165 | AC12: 0.047801977 | AD12: =IF(AND($G12="正式版",$H12="中西医诊所"),IFERROR(R12/同类汇总数据!C$3,0),IF(AND($G12="正式版",$H12="中医诊所"),IFERROR(R12/同类汇总数据!C$4,0),IF(AND($G12="正式版",$H12="口腔诊所"),IFERROR(R12/同类汇总数据!C$5,0),IF(AND($G12="检查版",$H12="中西医诊所"),IFERROR(R12/同类汇总数据!C$6,0),IF(AND($G12="检查版",$H12="中医诊所"),IFERROR(R12/同类汇总数据!C$7,0),IF(AND($G12="检查版",$H12="口腔诊所"),IFERROR(R12/同类汇总数据!C$8,0),IF(AND($G12="互联网版",$H12="中西医诊所"),IFERROR(R12/同类汇总数据!C$9,0),IF(AND($G12="互联网版",$H12="中医诊所"),IFERROR(R12/同类汇总数据!C$10,0),IF(AND($G12="互联网版",$H12="口腔诊所"),IFERROR(R12/同类汇总数据!C$11,0)))))))))) -> 6.6926381 | AE12: =IF(AND($G12="正式版",$H12="中西医诊所"),IFERROR(S12/同类汇总数据!D$3,0),IF(AND($G12="正式版",$H12="中医诊所"),IFERROR(S12/同类汇总数据!D$4,0),IF(AND($G12="正式版",$H12="口腔诊所"),IFERROR(S12/同类汇总数据!D$5,0),IF(AND($G12="检查版",$H12="中西医诊所"),IFERROR(S12/同类汇总数据!D$6,0),IF(AND($G12="检查版",$H12="中医诊所"),IFERROR(S12/同类汇总数据!D$7,0),IF(AND($G12="检查版",$H12="口腔诊所"),IFERROR(S12/同类汇总数据!D$8,0),IF(AND($G12="互联网版",$H12="中西医诊所"),IFERROR(S12/同类汇总数据!D$9,0),IF(AND($G12="互联网版",$H12="中医诊所"),IFERROR(S12/同类汇总数据!D$10,0),IF(AND($G12="互联网版",$H12="口腔诊所"),IFERROR(S12/同类汇总数据!D$11,0)))))))))) -> 6.7334708 | AF12: =IF(AND($G12="正式版",$H12="中西医诊所"),IFERROR(T12/同类汇总数据!E$3,0),IF(AND($G12="正式版",$H12="中医诊所"),IFERROR(T12/同类汇总数据!E$4,0),IF(AND($G12="正式版",$H12="口腔诊所"),IFERROR(T12/同类汇总数据!E$5,0),IF(AND($G12="检查版",$H12="中西医诊所"),IFERROR(T12/同类汇总数据!E$6,0),IF(AND($G12="检查版",$H12="中医诊所"),IFERROR(T12/同类汇总数据!E$7,0),IF(AND($G12="检查版",$H12="口腔诊所"),IFERROR(T12/同类汇总数据!E$8,0),IF(AND($G12="互联网版",$H12="中西医诊所"),IFERROR(T12/同类汇总数据!E$9,0),IF(AND($G12="互联网版",$H12="中医诊所"),IFERROR(T12/同类汇总数据!E$10,0),IF(AND($G12="互联网版",$H12="口腔诊所"),IFERROR(T12/同类汇总数据!E$11,0)))))))))) -> 6.4834048 | AG12: =IF(AND($G12="正式版",$H12="中西医诊所"),IFERROR(U12/同类汇总数据!F$3,0),IF(AND($G12="正式版",$H12="中医诊所"),IFERROR(U12/同类汇总数据!F$4,0),IF(AND($G12="正式版",$H12="口腔诊所"),IFERROR(U12/同类汇总数据!F$5,0),IF(AND($G12="检查版",$H12="中西医诊所"),IFERROR(U12/同类汇总数据!F$6,0),IF(AND($G12="检查版",$H12="中医诊所"),IFERROR(U12/同类汇总数据!F$7,0),IF(AND($G12="检查版",$H12="口腔诊所"),IFERROR(U12/同类汇总数据!F$8,0),IF(AND($G12="互联网版",$H12="中西医诊所"),IFERROR(U12/同类汇总数据!F$9,0),IF(AND($G12="互联网版",$H12="中医诊所"),IFERROR(U12/同类汇总数据!F$10,0),IF(AND($G12="互联网版",$H12="口腔诊所"),IFERROR(U12/同类汇总数据!F$11,0)))))))))) -> 6.7510847 | AH12: =IF(AND($G12="正式版",$H12="中西医诊所"),IFERROR(V12/同类汇总数据!G$3,0),IF(AND($G12="正式版",$H12="中医诊所"),IFERROR(V12/同类汇总数据!G$4,0),IF(AND($G12="正式版",$H12="口腔诊所"),IFERROR(V12/同类汇总数据!G$5,0),IF(AND($G12="检查版",$H12="中西医诊所"),IFERROR(V12/同类汇总数据!G$6,0),IF(AND($G12="检查版",$H12="中医诊所"),IFERROR(V12/同类汇总数据!G$7,0),IF(AND($G12="检查版",$H12="口腔诊所"),IFERROR(V12/同类汇总数据!G$8,0),IF(AND($G12="互联网版",$H12="中西医诊所"),IFERROR(V12/同类汇总数据!G$9,0),IF(AND($G12="互联网版",$H12="中医诊所"),IFERROR(V12/同类汇总数据!G$10,0),IF(AND($G12="互联网版",$H12="口腔诊所"),IFERROR(V12/同类汇总数据!G$11,0)))))))))) -> 6.6412612 | AI12: =IF(AND($G12="正式版",$H12="中西医诊所"),IFERROR(W12/同类汇总数据!H$3,0),IF(AND($G12="正式版",$H12="中医诊所"),IFERROR(W12/同类汇总数据!H$4,0),IF(AND($G12="正式版",$H12="口腔诊所"),IFERROR(W12/同类汇总数据!H$5,0),IF(AND($G12="检查版",$H12="中西医诊所"),IFERROR(W12/同类汇总数据!H$6,0),IF(AND($G12="检查版",$H12="中医诊所"),IFERROR(W12/同类汇总数据!H$7,0),IF(AND($G12="检查版",$H12="口腔诊所"),IFERROR(W12/同类汇总数据!H$8,0),IF(AND($G12="互联网版",$H12="中西医诊所"),IFERROR(W12/同类汇总数据!H$9,0),IF(AND($G12="互联网版",$H12="中医诊所"),IFERROR(W12/同类汇总数据!H$10,0),IF(AND($G12="互联网版",$H12="口腔诊所"),IFERROR(W12/同类汇总数据!H$11,0)))))))))) -> 7.0810462 | AJ12: =IF(AND($G12="正式版",$H12="中西医诊所"),IFERROR(X12/同类汇总数据!I$3,0),IF(AND($G12="正式版",$H12="中医诊所"),IFERROR(X12/同类汇总数据!I$4,0),IF(AND($G12="正式版",$H12="口腔诊所"),IFERROR(X12/同类汇总数据!I$5,0),IF(AND($G12="检查版",$H12="中西医诊所"),IFERROR(X12/同类汇总数据!I$6,0),IF(AND($G12="检查版",$H12="中医诊所"),IFERROR(X12/同类汇总数据!I$7,0),IF(AND($G12="检查版",$H12="口腔诊所"),IFERROR(X12/同类汇总数据!I$8,0),IF(AND($G12="互联网版",$H12="中西医诊所"),IFERROR(X12/同类汇总数据!I$9,0),IF(AND($G12="互联网版",$H12="中医诊所"),IFERROR(X12/同类汇总数据!I$10,0),IF(AND($G12="互联网版",$H12="口腔诊所"),IFERROR(X12/同类汇总数据!I$11,0)))))))))) -> 6.7171421 | AK12: =IF(AND($G12="正式版",$H12="中西医诊所"),IFERROR(Y12/同类汇总数据!J$3,0),IF(AND($G12="正式版",$H12="中医诊所"),IFERROR(Y12/同类汇总数据!J$4,0),IF(AND($G12="正式版",$H12="口腔诊所"),IFERROR(Y12/同类汇总数据!J$5,0),IF(AND($G12="检查版",$H12="中西医诊所"),IFERROR(Y12/同类汇总数据!J$6,0),IF(AND($G12="检查版",$H12="中医诊所"),IFERROR(Y12/同类汇总数据!J$7,0),IF(AND($G12="检查版",$H12="口腔诊所"),IFERROR(Y12/同类汇总数据!J$8,0),IF(AND($G12="互联网版",$H12="中西医诊所"),IFERROR(Y12/同类汇总数据!J$9,0),IF(AND($G12="互联网版",$H12="中医诊所"),IFERROR(Y12/同类汇总数据!J$10,0),IF(AND($G12="互联网版",$H12="口腔诊所"),IFERROR(Y12/同类汇总数据!J$11,0)))))))))) -> 6.8720198 | AL12: =IF(YEAR(AO12)<YEAR(TODAY()),"今年内未操作",IF(DATEDIF(AO12,$B$1,"d")>90,"最近三月未操作",IF(DATEDIF(AO12,$B$1,"d")>30,"最近一月未操作",IF(DATEDIF(AO12,$B$1,"d")>7,"最近一周未操作","-")))) -> - | AM12: =IF(AE12<0.2,"低于同行20%",IF(AE12<0.5,"低于同行50%",IF(AE12>=2,"高于同行100%",IF(AE12>=1.5,"高于同行150%",IF(AE12>=1.2,"高于同行20%",""))))) -> 高于同行100% | AN12: =IF(AI12<0.2,"低于同行20%",IF(AI12<0.5,"低于同行50%",IF(AI12>=2,"高于同行100%",IF(AI12>=1.5,"高于同行150%",IF(AI12>=1.2,"高于同行20%",""))))) -> 高于同行100% | AO12: =MAX(IF(M12<>"",M12,0),IF(N12<>"",N12,0),IF(O12<>"",O12,0),IF(P12<>"",P12,0),IF(Q12<>"",Q12,0)) -> 46104.4 | AP12: =IF(AND(DATEDIF(AQ12,$B$1,"d")<=14,DATEDIF(N12,$B$1,"d")>14),"未支付","") | AQ12: 45043.974
A13: =ROW()-3 -> 10 | B13: =IF(V13=0,"无交易",IF(AND(Y13<=-0.2,Z13<=-0.2,AA13<=-0.2),"连续三月交易下滑",IF(AND(Y13>=0.2,Z13>=0.2,AA13>=0.2),"连续三月交易上升",IF(AND(Y13<0.2,Y13>-0.2,Z13<0.2,Z13>-0.2,AA13<0.2,AA13>-0.2),"交易平稳",IF(OR(ABS(Y13-Z13)>=0.2,ABS(Z13-AA13)>=0.2),"交易波动较大","-"))))) -> 连续三月交易上升 | C13: =IF(AA13<=-0.5,"本月交易额降超50%",IF(AA13<=-0.2,"本月交易额降超20%","")) | D13: =IF(DATEDIF(AO13,$B$1,"d")>30,"流失",IF(AND(DATEDIF(AO13,$B$1,"d")>7,DATEDIF(AO13,$B$1,"d")<=30),"可能流失",IF(AND(DATEDIF(AO13,$B$1,"d")<=7,DATEDIF(AO13,$B$1,"d")>3),"即将流失","-"))) -> - | E13: 1596128897364439042 | F13: 45043.974 | G13: 正式版 | H13: 口腔诊所 | I13: 四川省甘孜州 | J13: 康定市 | K13: 康定斯迈尔口腔诊所有限责任公司新市前街诊所 | L13: 四川省甘孜州康定市 | M13: 46103.39 | N13: 46103.613 | O13: 46103.613 | P13: 44896.57 | R13: 14800 | S13: 49510 | T13: 140070 | U13: 125460 | V13: 19 | W13: 69 | X13: 198 | Y13: 175 | Z13: 864.54545 | AA13: 0.25628013 | AB13: -0.22952102 | AC13: 0.058129913 | AD13: =IF(AND($G13="正式版",$H13="中西医诊所"),IFERROR(R13/同类汇总数据!C$3,0),IF(AND($G13="正式版",$H13="中医诊所"),IFERROR(R13/同类汇总数据!C$4,0),IF(AND($G13="正式版",$H13="口腔诊所"),IFERROR(R13/同类汇总数据!C$5,0),IF(AND($G13="检查版",$H13="中西医诊所"),IFERROR(R13/同类汇总数据!C$6,0),IF(AND($G13="检查版",$H13="中医诊所"),IFERROR(R13/同类汇总数据!C$7,0),IF(AND($G13="检查版",$H13="口腔诊所"),IFERROR(R13/同类汇总数据!C$8,0),IF(AND($G13="互联网版",$H13="中西医诊所"),IFERROR(R13/同类汇总数据!C$9,0),IF(AND($G13="互联网版",$H13="中医诊所"),IFERROR(R13/同类汇总数据!C$10,0),IF(AND($G13="互联网版",$H13="口腔诊所"),IFERROR(R13/同类汇总数据!C$11,0)))))))))) -> 1.4803636 | AE13: =IF(AND($G13="正式版",$H13="中西医诊所"),IFERROR(S13/同类汇总数据!D$3,0),IF(AND($G13="正式版",$H13="中医诊所"),IFERROR(S13/同类汇总数据!D$4,0),IF(AND($G13="正式版",$H13="口腔诊所"),IFERROR(S13/同类汇总数据!D$5,0),IF(AND($G13="检查版",$H13="中西医诊所"),IFERROR(S13/同类汇总数据!D$6,0),IF(AND($G13="检查版",$H13="中医诊所"),IFERROR(S13/同类汇总数据!D$7,0),IF(AND($G13="检查版",$H13="口腔诊所"),IFERROR(S13/同类汇总数据!D$8,0),IF(AND($G13="互联网版",$H13="中西医诊所"),IFERROR(S13/同类汇总数据!D$9,0),IF(AND($G13="互联网版",$H13="中医诊所"),IFERROR(S13/同类汇总数据!D$10,0),IF(AND($G13="互联网版",$H13="口腔诊所"),IFERROR(S13/同类汇总数据!D$11,0)))))))))) -> 1.1399738 | AF13: =IF(AND($G13="正式版",$H13="中西医诊所"),IFERROR(T13/同类汇总数据!E$3,0),IF(AND($G13="正式版",$H13="中医诊所"),IFERROR(T13/同类汇总数据!E$4,0),IF(AND($G13="正式版",$H13="口腔诊所"),IFERROR(T13/同类汇总数据!E$5,0),IF(AND($G13="检查版",$H13="中西医诊所"),IFERROR(T13/同类汇总数据!E$6,0),IF(AND($G13="检查版",$H13="中医诊所"),IFERROR(T13/同类汇总数据!E$7,0),IF(AND($G13="检查版",$H13="口腔诊所"),IFERROR(T13/同类汇总数据!E$8,0),IF(AND($G13="互联网版",$H13="中西医诊所"),IFERROR(T13/同类汇总数据!E$9,0),IF(AND($G13="互联网版",$H13="中医诊所"),IFERROR(T13/同类汇总数据!E$10,0),IF(AND($G13="互联网版",$H13="口腔诊所"),IFERROR(T13/同类汇总数据!E$11,0)))))))))) -> 1.2634061 | AG13: =IF(AND($G13="正式版",$H13="中西医诊所"),IFERROR(U13/同类汇总数据!F$3,0),IF(AND($G13="正式版",$H13="中医诊所"),IFERROR(U13/同类汇总数据!F$4,0),IF(AND($G13="正式版",$H13="口腔诊所"),IFERROR(U13/同类汇总数据!F$5,0),IF(AND($G13="检查版",$H13="中西医诊所"),IFERROR(U13/同类汇总数据!F$6,0),IF(AND($G13="检查版",$H13="中医诊所"),IFERROR(U13/同类汇总数据!F$7,0),IF(AND($G13="检查版",$H13="口腔诊所"),IFERROR(U13/同类汇总数据!F$8,0),IF(AND($G13="互联网版",$H13="中西医诊所"),IFERROR(U13/同类汇总数据!F$9,0),IF(AND($G13="互联网版",$H13="中医诊所"),IFERROR(U13/同类汇总数据!F$10,0),IF(AND($G13="互联网版",$H13="口腔诊所"),IFERROR(U13/同类汇总数据!F$11,0)))))))))) -> 1.255881 | AH13: =IF(AND($G13="正式版",$H13="中西医诊所"),IFERROR(V13/同类汇总数据!G$3,0),IF(AND($G13="正式版",$H13="中医诊所"),IFERROR(V13/同类汇总数据!G$4,0),IF(AND($G13="正式版",$H13="口腔诊所"),IFERROR(V13/同类汇总数据!G$5,0),IF(AND($G13="检查版",$H13="中西医诊所"),IFERROR(V13/同类汇总数据!G$6,0),IF(AND($G13="检查版",$H13="中医诊所"),IFERROR(V13/同类汇总数据!G$7,0),IF(AND($G13="检查版",$H13="口腔诊所"),IFERROR(V13/同类汇总数据!G$8,0),IF(AND($G13="互联网版",$H13="中西医诊所"),IFERROR(V13/同类汇总数据!G$9,0),IF(AND($G13="互联网版",$H13="中医诊所"),IFERROR(V13/同类汇总数据!G$10,0),IF(AND($G13="互联网版",$H13="口腔诊所"),IFERROR(V13/同类汇总数据!G$11,0)))))))))) -> 1.4119675 | AI13: =IF(AND($G13="正式版",$H13="中西医诊所"),IFERROR(W13/同类汇总数据!H$3,0),IF(AND($G13="正式版",$H13="中医诊所"),IFERROR(W13/同类汇总数据!H$4,0),IF(AND($G13="正式版",$H13="口腔诊所"),IFERROR(W13/同类汇总数据!H$5,0),IF(AND($G13="检查版",$H13="中西医诊所"),IFERROR(W13/同类汇总数据!H$6,0),IF(AND($G13="检查版",$H13="中医诊所"),IFERROR(W13/同类汇总数据!H$7,0),IF(AND($G13="检查版",$H13="口腔诊所"),IFERROR(W13/同类汇总数据!H$8,0),IF(AND($G13="互联网版",$H13="中西医诊所"),IFERROR(W13/同类汇总数据!H$9,0),IF(AND($G13="互联网版",$H13="中医诊所"),IFERROR(W13/同类汇总数据!H$10,0),IF(AND($G13="互联网版",$H13="口腔诊所"),IFERROR(W13/同类汇总数据!H$11,0)))))))))) -> 1.2150818 | AJ13: =IF(AND($G13="正式版",$H13="中西医诊所"),IFERROR(X13/同类汇总数据!I$3,0),IF(AND($G13="正式版",$H13="中医诊所"),IFERROR(X13/同类汇总数据!I$4,0),IF(AND($G13="正式版",$H13="口腔诊所"),IFERROR(X13/同类汇总数据!I$5,0),IF(AND($G13="检查版",$H13="中西医诊所"),IFERROR(X13/同类汇总数据!I$6,0),IF(AND($G13="检查版",$H13="中医诊所"),IFERROR(X13/同类汇总数据!I$7,0),IF(AND($G13="检查版",$H13="口腔诊所"),IFERROR(X13/同类汇总数据!I$8,0),IF(AND($G13="互联网版",$H13="中西医诊所"),IFERROR(X13/同类汇总数据!I$9,0),IF(AND($G13="互联网版",$H13="中医诊所"),IFERROR(X13/同类汇总数据!I$10,0),IF(AND($G13="互联网版",$H13="口腔诊所"),IFERROR(X13/同类汇总数据!I$11,0)))))))))) -> 1.3419953 | AK13: =IF(AND($G13="正式版",$H13="中西医诊所"),IFERROR(Y13/同类汇总数据!J$3,0),IF(AND($G13="正式版",$H13="中医诊所"),IFERROR(Y13/同类汇总数据!J$4,0),IF(AND($G13="正式版",$H13="口腔诊所"),IFERROR(Y13/同类汇总数据!J$5,0),IF(AND($G13="检查版",$H13="中西医诊所"),IFERROR(Y13/同类汇总数据!J$6,0),IF(AND($G13="检查版",$H13="中医诊所"),IFERROR(Y13/同类汇总数据!J$7,0),IF(AND($G13="检查版",$H13="口腔诊所"),IFERROR(Y13/同类汇总数据!J$8,0),IF(AND($G13="互联网版",$H13="中西医诊所"),IFERROR(Y13/同类汇总数据!J$9,0),IF(AND($G13="互联网版",$H13="中医诊所"),IFERROR(Y13/同类汇总数据!J$10,0),IF(AND($G13="互联网版",$H13="口腔诊所"),IFERROR(Y13/同类汇总数据!J$11,0)))))))))) -> 1.3177006 | AL13: =IF(YEAR(AO13)<YEAR(TODAY()),"今年内未操作",IF(DATEDIF(AO13,$B$1,"d")>90,"最近三月未操作",IF(DATEDIF(AO13,$B$1,"d")>30,"最近一月未操作",IF(DATEDIF(AO13,$B$1,"d")>7,"最近一周未操作","-")))) -> - | AM13: =IF(AE13<0.2,"低于同行20%",IF(AE13<0.5,"低于同行50%",IF(AE13>=2,"高于同行100%",IF(AE13>=1.5,"高于同行150%",IF(AE13>=1.2,"高于同行20%",""))))) | AN13: =IF(AI13<0.2,"低于同行20%",IF(AI13<0.5,"低于同行50%",IF(AI13>=2,"高于同行100%",IF(AI13>=1.5,"高于同行150%",IF(AI13>=1.2,"高于同行20%",""))))) -> 高于同行20% | AO13: =MAX(IF(M13<>"",M13,0),IF(N13<>"",N13,0),IF(O13<>"",O13,0),IF(P13<>"",P13,0),IF(Q13<>"",Q13,0)) -> 46103.613 | AP13: =IF(AND(DATEDIF(AQ13,$B$1,"d")<=14,DATEDIF(N13,$B$1,"d")>14),"未支付","") | AQ13: 45043.974
